Workbook

Sheet Summary
G2: 44926 | H2: 45291 | I2: 45657 | J2: 46022 | K2: 46387 | L2: 46752 | M2: 47118 | N2: 47483
C3: COKE | D3: COKE US Equity | G3: 2022 | H3: =G3+1 -> 2023 | I3: =H3+1 -> 2024 | J3: =I3+1 -> 2025 | K3: =J3+1 -> 2026 | L3: =K3+1 -> 2027 | M3: =L3+1 -> 2028 | N3: =M3+1 -> 2029 | Q3: 2026 YE return scenarios
C4: Scenario | D4: 2 - Base | F4: WH Revenue | G4: ='WH Model'!BQ17 -> 6200.957 | H4: ='WH Model'!BR17 -> 6653.858 | I4: ='WH Model'!BS17 -> 6899.716 | J4: ='WH Model'!BT17 -> 7228.055 | K4: ='WH Model'!BU17 -> 7420.7786 | L4: ='WH Model'!BV17 -> 7644.7594 | M4: ='WH Model'!BW17 -> 7875.5006 | N4: ='WH Model'!BX17 -> 8113.2062 | Q4: EPS | R4: P/E | S4: Target | T4: NPV | U4: % Return | V4: IRR
C5: Last Updated | D5: =TODAY() -> 46148 | F5: % yoy | H5: =IF(G4=0,0,H4/G4-1) -> 0.073037275 | I5: =IF(H4=0,0,I4/H4-1) -> 0.036949691 | J5: =IF(I4=0,0,J4/I4-1) -> 0.047587321 | K5: =IF(J4=0,0,K4/J4-1) -> 0.026663279 | L5: =IF(K4=0,0,L4/K4-1) -> 0.030182918 | M5: =IF(L4=0,0,M4/L4-1) -> 0.030182921 | N5: =IF(M4=0,0,N4/M4-1) -> 0.030182924 | P5: Bull | Q5: =IF(VALUE(LEFT($D$4,1))=1,$L$22,Q5) -> 8.8284404 | R5: 24 | S5: =Q5*R5 -> 211.88257 | T5: =S5/1.1^(($L$2-$D$5)/365) -> 180.96677 | U5: =S5/$D$7-1 -> -0.016329756 | V5: =(1+U5)^(1/(($L$2-$D$5)/365))-1 -> -0.0099002737
C6: Cap Table (USD) | F6: Expected Delta | P6: Base | Q6: =IF(VALUE(LEFT($D$4,1))=2,$L$22,Q6) -> 6.3732891 | R6: 17 | S6: =Q6*R6 -> 108.34591 | T6: =S6/1.1^(($L$2-$D$5)/365) -> 92.537157 | U6: =S6/$D$7-1 -> -0.49700133 | V6: =(1+U6)^(1/(($L$2-$D$5)/365))-1 -> -0.3398305
C7: ="Price as of "&TEXT(TODAY(),"mm/dd/yyyy") -> Price as of 05/06/2026 | D7: {=_xll.BQL("COKE US EQUITY","PX_LAST")} -> 215.4 | P7: Bear | Q7: =IF(VALUE(LEFT($D$4,1))=3,$L$22,Q7) -> 3.7673979 | R7: 15 | S7: =Q7*R7 -> 56.510969 | T7: =S7/1.1^(($L$2-$D$5)/365) -> 48.265451 | U7: =S7/$D$7-1 -> -0.73764638 | V7: =(1+U7)^(1/(($L$2-$D$5)/365))-1 -> -0.55451739
C8: Diluted Shares | D8: ='WH Model'!AT50 -> 57.020861
C9: Market Cap | D9: =D7*D8 -> 12282.294 | F9: Street Revenue | G9: =G4 -> 6200.957 | H9: =H4 -> 6653.858 | I9: =I4 -> 6899.716 | J9: =J4 -> 7228.055 | Q9: 2026 YE return scenarios
C10: Total Debt | D10: ='WH Model'!AS55 -> 2787.753 | F10: % yoy | H10: =IF(G9=0,0,H9/G9-1) -> 0.073037275 | I10: =IF(H9=0,0,I9/H9-1) -> 0.036949691 | J10: =IF(I9=0,0,J9/I9-1) -> 0.047587321 | Q10: EBITDA | R10: EV/EBITDA | S10: Target | T10: NPV | U10: % Return | V10: IRR
C11: Cash | D11: ='WH Model'!AS54 -> 281.918 | P11: Bull | Q11: =IF(VALUE(LEFT($D$4,1))=1,$L$12,Q11) -> 1107.1949 | R11: 14 | S11: =((Q11*R11)-$L$37)/$L$36 -> 226.84572 | T11: =S11/1.1^(($L$2-$D$5)/365) -> 193.74665 | U11: =S11/$D$7-1 -> 0.05313706 | V11: =(1+U11)^(1/(($L$2-$D$5)/365))-1 -> 0.031781477
C12: Net Debt | D12: =D10-D11 -> 2505.835 | F12: WH EBITDA | G12: ='WH Model'!BQ35 -> 812.637 | H12: ='WH Model'!BR35 -> 1011.417 | I12: ='WH Model'!BS35 -> 1114.141 | J12: ='WH Model'!BT35 -> 1169.186 | K12: ='WH Model'!BU35 -> 872.08423 | L12: ='WH Model'!BV35 -> 914.7749 | M12: ='WH Model'!BW35 -> 949.49929 | N12: ='WH Model'!BX35 -> 948.28863 | P12: Base | Q12: =IF(VALUE(LEFT($D$4,1))=2,$L$12,Q12) -> 914.7749 | R12: 12 | S12: =((Q12*R12)-$L$37)/$L$36 -> 146.74344 | T12: =S12/1.1^(($L$2-$D$5)/365) -> 125.33209 | U12: =S12/$D$7-1 -> -0.31873985 | V12: =(1+U12)^(1/(($L$2-$D$5)/365))-1 -> -0.20700534
C13: NCI | D13: 0 | F13: % margin | G13: =IF(G4=0,0,G12/G4) -> 0.13105026 | H13: =IF(H4=0,0,H12/H4) -> 0.1520046 | I13: =IF(I4=0,0,I12/I4) -> 0.16147636 | J13: =IF(J4=0,0,J12/J4) -> 0.16175666 | K13: =IF(K4=0,0,K12/K4) -> 0.11751924 | L13: =IF(L4=0,0,L12/L4) -> 0.11966039 | M13: =IF(M4=0,0,M12/M4) -> 0.12056368 | N13: =IF(N4=0,0,N12/N4) -> 0.11688211 | P13: Bear | Q13: =IF(VALUE(LEFT($D$4,1))=3,$L$12,Q13) -> 708.72245 | R13: 8 | S13: =((Q13*R13)-$L$37)/$L$36 -> 52.756263 | T13: =S13/1.1^(($L$2-$D$5)/365) -> 45.058594 | U13: =S13/$D$7-1 -> -0.7550777 | V13: =(1+U13)^(1/(($L$2-$D$5)/365))-1 -> -0.57264677
C14: Enterprise Value | D14: =D9+D12+D13 -> 14788.129 | F14: % yoy | H14: =IF(G12=0,0,H12/G12-1) -> 0.24461106 | I14: =IF(H12=0,0,I12/H12-1) -> 0.10156444 | J14: =IF(I12=0,0,J12/I12-1) -> 0.049405775 | K14: =IF(J12=0,0,K12/J12-1) -> -0.25410993 | L14: =IF(K12=0,0,L12/K12-1) -> 0.048952457 | M14: =IF(L12=0,0,M12/L12-1) -> 0.037959497 | N14: =IF(M12=0,0,N12/M12-1) -> -0.0012750506
F15: Expected Delta
Q16: Quick Valuation
Q17: Metric | R17: Multiple | S17: Implied Price
F18: Street EBITDA | G18: =G12 -> 812.637 | H18: =H12 -> 1011.417 | I18: =I12 -> 1114.141 | J18: =J12 -> 1169.186 | P18: P/E | S18: =Q18*R18 -> 0
F19: % margin | G19: =IF(G9=0,0,G18/G9) -> 0.13105026 | H19: =IF(H9=0,0,H18/H9) -> 0.1520046 | I19: =IF(I9=0,0,I18/I9) -> 0.16147636 | J19: =IF(J9=0,0,J18/J9) -> 0.16175666 | P19: EV/EBITDA | Q19: 1100 | R19: 11 | S19: =((Q19*R19)-$D$12)/$D$8 -> 168.2571
F20: % yoy | H20: =IF(G18=0,0,H18/G18-1) -> 0.24461106 | I20: =IF(H18=0,0,I18/H18-1) -> 0.10156444 | J20: =IF(I18=0,0,J18/I18-1) -> 0.049405775
F22: WH EPS | G22: ='WH Model'!BQ51 -> 4.8638753 | H22: ='WH Model'!BR51 -> 6.5353207 | I22: ='WH Model'!BS51 -> 7.4929137 | J22: ='WH Model'!BT51 -> 7.9609262 | K22: ='WH Model'!BU51 -> 5.8541141 | L22: ='WH Model'!BV51 -> 6.3732891 | M22: ='WH Model'!BW51 -> 6.8028388 | N22: ='WH Model'!BX51 -> 6.7569824
F23: % yoy | H23: =IF(G22=0,0,H22/G22-1) -> 0.3436448 | I23: =IF(H22=0,0,I22/H22-1) -> 0.14652578 | J23: =IF(I22=0,0,J22/I22-1) -> 0.062460674 | K23: =IF(J22=0,0,K22/J22-1) -> -0.26464409 | L23: =IF(K22=0,0,L22/K22-1) -> 0.088685492 | M23: =IF(L22=0,0,M22/L22-1) -> 0.067398442 | N23: =IF(M22=0,0,N22/M22-1) -> -0.0067407738
F24: Street EPS | G24: =G22 -> 4.8638753 | H24: =H22 -> 6.5353207 | I24: =I22 -> 7.4929137 | J24: =J22 -> 7.9609262
F25: % yoy | H25: =IF(G24=0,0,H24/G24-1) -> 0.3436448 | I25: =IF(H24=0,0,I24/H24-1) -> 0.14652578 | J25: =IF(I24=0,0,J24/I24-1) -> 0.062460674
F26: Expected Delta
F29: Valuation | G29: 2022 | H29: 2023 | I29: 2024 | J29: 2025 | K29: 2026 | L29: 2027 | M29: 2028 | N29: 2029
F30: EV/Sales | G30: =IF(G4=0,0,$D$14/G4) -> 2.3848139 | H30: =IF(H4=0,0,$D$14/H4) -> 2.2224893 | I30: =IF(I4=0,0,$D$14/I4) -> 2.1432953 | J30: =IF(J4=0,0,$D$14/J4) -> 2.0459347 | K30: =IF(K4=0,0,$D$14/K4) -> 1.9928001 | L30: =IF(L4=0,0,$D$14/L4) -> 1.9344139 | M30: =IF(M4=0,0,$D$14/M4) -> 1.8777382 | N30: =IF(N4=0,0,$D$14/N4) -> 1.8227231
F31: Street EV/Sales | G31: =IF(G9=0,0,$D$14/G9) -> 2.3848139 | H31: =IF(H9=0,0,$D$14/H9) -> 2.2224893 | I31: =IF(I9=0,0,$D$14/I9) -> 2.1432953 | J31: =IF(J9=0,0,$D$14/J9) -> 2.0459347 | K31: =IF(K9=0,0,$D$14/K9) -> 0 | L31: =IF(L9=0,0,$D$14/L9) -> 0 | M31: =IF(M9=0,0,$D$14/M9) -> 0 | N31: =IF(N9=0,0,$D$14/N9) -> 0
F32: Street EV/EBITDA | G32: =IF(G18=0,0,$D$14/G18) -> 18.197705 | H32: =IF(H18=0,0,$D$14/H18) -> 14.621198 | I32: =IF(I18=0,0,$D$14/I18) -> 13.273121 | J32: =IF(J18=0,0,$D$14/J18) -> 12.648226 | K32: =IF(K18=0,0,$D$14/K18) -> 0 | L32: =IF(L18=0,0,$D$14/L18) -> 0 | M32: =IF(M18=0,0,$D$14/M18) -> 0 | N32: =IF(N18=0,0,$D$14/N18) -> 0
F33: WH EV/EBITDA | G33: =IF(G12=0,0,$D$14/G12) -> 18.197705 | H33: =IF(H12=0,0,$D$14/H12) -> 14.621198 | I33: =IF(I12=0,0,$D$14/I12) -> 13.273121 | J33: =IF(J12=0,0,$D$14/J12) -> 12.648226 | K33: =IF(K12=0,0,$D$14/K12) -> 16.957225 | L33: =IF(L12=0,0,$D$14/L12) -> 16.165866 | M33: =IF(M12=0,0,$D$14/M12) -> 15.57466 | N33: =IF(N12=0,0,$D$14/N12) -> 15.594544
F34: WH P/E | G34: =IF(G22=0,0,$D$7/G22) -> 44.285675 | H34: =IF(H22=0,0,$D$7/H22) -> 32.959362 | I34: =IF(I22=0,0,$D$7/I22) -> 28.747161 | J34: =IF(J22=0,0,$D$7/J22) -> 27.057153 | K34: =IF(K22=0,0,$D$7/K22) -> 36.794636 | L34: =IF(L22=0,0,$D$7/L22) -> 33.797306 | M34: =IF(M22=0,0,$D$7/M22) -> 31.663252 | N34: =IF(N22=0,0,$D$7/N22) -> 31.878135
F35: Street P/E | G35: =IF(G24=0,0,$D$7/G24) -> 44.285675 | H35: =IF(H24=0,0,$D$7/H24) -> 32.959362 | I35: =IF(I24=0,0,$D$7/I24) -> 28.747161 | J35: =IF(J24=0,0,$D$7/J24) -> 27.057153 | K35: =IF(K24=0,0,$D$7/K24) -> 0 | L35: =IF(L24=0,0,$D$7/L24) -> 0 | M35: =IF(M24=0,0,$D$7/M24) -> 0 | N35: =IF(N24=0,0,$D$7/N24) -> 0
F36: Shares Outstanding | G36: ='WH Model'!BQ50 -> 93.98 | H36: ='WH Model'!BR50 -> 93.925 | I36: ='WH Model'!BS50 -> 90.5625 | J36: ='WH Model'!BT50 -> 83.96925 | K36: ='WH Model'!BU50 -> 56.879453 | L36: ='WH Model'!BV50 -> 56.470676 | M36: ='WH Model'!BW50 -> 55.962029 | N36: ='WH Model'!BX50 -> 55.407533
F37: Net Debt | G37: ='WH Model'!BQ57 -> 647.05775 | H37: ='WH Model'!BR57 -> 247.9245 | I37: ='WH Model'!BS57 -> 492.52625 | J37: ='WH Model'!BT57 -> 1110.5345 | K37: ='WH Model'!BU57 -> 2653.2905 | L37: ='WH Model'!BV57 -> 2690.5977 | M37: ='WH Model'!BW57 -> 2716.0026 | N37: ='WH Model'!BX57 -> 2742.4803
F38: Adj. TEV | G38: =G37+$D$9 -> 12929.351 | H38: =H37+$D$9 -> 12530.218 | I38: =I37+$D$9 -> 12774.82 | J38: =J37+$D$9 -> 13392.828 | K38: =K37+$D$9 -> 14935.584 | L38: =L37+$D$9 -> 14972.891 | M38: =M37+$D$9 -> 14998.296 | N38: =N37+$D$9 -> 15024.774

Sheet WH Model
A1: COKE | F1: 16 | G1: =F1 -> 16 | H1: =G1 -> 16 | I1: =H1 -> 16 | J1: =I1+1 -> 17 | K1: =J1 -> 17 | L1: =K1 -> 17 | M1: =L1 -> 17 | N1: =M1+1 -> 18 | O1: =N1 -> 18 | P1: =O1 -> 18 | Q1: =P1 -> 18 | R1: =Q1+1 -> 19 | S1: =R1 -> 19 | T1: =S1 -> 19 | U1: =T1 -> 19 | V1: =U1+1 -> 20 | W1: =V1 -> 20 | X1: =W1 -> 20 | Y1: =X1 -> 20 | Z1: =Y1+1 -> 21 | AA1: =Z1 -> 21 | AB1: =AA1 -> 21 | AC1: =AB1 -> 21 | AD1: =AC1+1 -> 22 | AE1: =AD1 -> 22 | AF1: =AE1 -> 22 | AG1: =AF1 -> 22 | AH1: =AG1+1 -> 23 | AI1: =AH1 -> 23 | AJ1: =AI1 -> 23 | AK1: =AJ1 -> 23 | AL1: =AK1+1 -> 24 | AM1: =AL1 -> 24 | AN1: =AM1 -> 24 | AO1: =AN1 -> 24 | AP1: =AO1+1 -> 25 | AQ1: =AP1 -> 25 | AR1: =AQ1 -> 25 | AS1: =AR1 -> 25 | AT1: =AS1+1 -> 26 | AU1: =AT1 -> 26 | AV1: =AU1 -> 26 | AW1: =AV1 -> 26 | AX1: =AW1+1 -> 27 | AY1: =AX1 -> 27 | AZ1: =AY1 -> 27 | BA1: =AZ1 -> 27 | BB1: =BA1+1 -> 28 | BC1: =BB1 -> 28 | BD1: =BC1 -> 28 | BE1: =BD1 -> 28 | BF1: =BE1+1 -> 29 | BG1: =BF1 -> 29 | BH1: =BG1 -> 29 | BI1: =BH1 -> 29 | BK1: 16 | BL1: 17 | BM1: 18 | BN1: 19 | BO1: 20 | BP1: 21 | BQ1: 22 | BR1: 23 | BS1: 24 | BT1: 25 | BU1: 26 | BV1: 27 | BW1: 28 | BX1: 29
A2: Coca-Cola Consolidated, Inc. | F2: Q1 | G2: Q2 | H2: Q3 | I2: Q4 | J2: =F2 -> Q1 | K2: =G2 -> Q2 | L2: =H2 -> Q3 | M2: =I2 -> Q4 | N2: =J2 -> Q1 | O2: =K2 -> Q2 | P2: =L2 -> Q3 | Q2: =M2 -> Q4 | ... BI2: =BE2 -> Q4 | BK2: Q4 | BL2: Q4 | BM2: Q4 | BN2: Q4 | BO2: Q4 | BP2: Q4 | BQ2: Q4 | BR2: Q4 | BS2: Q4 | BT2: Q4 | BU2: Q4 | BV2: Q4 | BW2: Q4 | BX2: Q4
A3: ($ in mm, except per share values) | F3: 90 | G3: 91 | H3: 92 | I3: 92 | J3: 90 | K3: 91 | L3: 92 | M3: 92 | N3: 90 | O3: 91 | P3: 92 | Q3: 92 | R3: 90 | S3: 91 | T3: 92 | U3: 92 | V3: 90 | W3: 91 | X3: 92 | Y3: 92 | Z3: 90 | AA3: 91 | AB3: 92 | AC3: 92 | AD3: 90 | AE3: 91 | AF3: 92 | AG3: 92 | AH3: 90 | AI3: 91 | AJ3: 92 | AK3: 92 | AL3: 90 | AM3: 91 | AN3: 92 | AO3: 92 | AP3: 90 | AQ3: 91 | AR3: 92 | AS3: 92 | AT3: 90 | AU3: 91 | AV3: 92 | AW3: 92 | AX3: 90 | AY3: 91 | AZ3: 92 | BA3: 92 | BB3: 90 | BC3: 91 | BD3: 92 | BE3: 92 | BF3: 90 | BG3: 91 | BH3: 92 | BI3: 92
F4: 42460 | G4: =EOMONTH(F4,3) -> 42551 | H4: =EOMONTH(G4,3) -> 42643 | I4: =EOMONTH(H4,3) -> 42735 | J4: =EOMONTH(I4,3) -> 42825 | K4: =EOMONTH(J4,3) -> 42916 | L4: =EOMONTH(K4,3) -> 43008 | M4: =EOMONTH(L4,3) -> 43100 | N4: =EOMONTH(M4,3) -> 43190 | ... BI4: =EOMONTH(BH4,3) -> 47483
F5: Q1 16 | G5: =G2&" "&G1 -> Q2 16 | H5: =H2&" "&H1 -> Q3 16 | I5: =I2&" "&I1 -> Q4 16 | J5: =J2&" "&J1 -> Q1 17 | K5: =K2&" "&K1 -> Q2 17 | L5: =L2&" "&L1 -> Q3 17 | M5: =M2&" "&M1 -> Q4 17 | N5: =N2&" "&N1 -> Q1 18 | ... BI5: =BI2&" "&BI1 -> Q4 29 | BK5: 2016 | BL5: 2017 | BM5: 2018 | BN5: 2019 | BO5: 2020 | BP5: 2021 | BQ5: 2022 | BR5: 2023 | BS5: 2024 | BT5: 2025 | BU5: 2026 | BV5: 2027 | BW5: 2028 | BX5: 2029
A6: x | B6: Drivers
B7: Tax Rate | F7: =F25/F24 -> 0.3598611 | G7: =G25/G24 -> 0.38044489 | H7: =H25/H24 -> 0.33927186 | I7: =I25/I24 -> 0.43217956 | J7: =J25/J24 -> 0.4552294 | K7: =K25/K24 -> 0.33053691 | L7: =L25/L24 -> 0.38318275 | M7: =M25/M24 -> -1.7727164 | ... AS7: =AS25/AS24 -> 0.27081175 | AT7: 0.25 | AU7: 0.25 | AV7: 0.25 | AW7: 0.25 | AX7: 0.25 | AY7: 0.25 | AZ7: 0.25 | BA7: 0.25 | BB7: 0.25 | BC7: 0.25 | BD7: 0.25 | BE7: 0.25 | BF7: 0.25 | BG7: 0.25 | BH7: 0.25 | BI7: 0.25 | BK7: =BK25/BK24 -> 0.38882777 | BL7: =BL25/BL24 -> -0.6323366 | BM7: =BM25/BM24 -> -0.14066381 | BN7: =BN25/BN24 -> 0.45770636 | BO7: =BO25/BO24 -> 0.24453618 | BP7: =BP25/BP24 -> 0.25698317 | BQ7: =BQ25/BQ24 -> 0.2520123 | BR7: =BR25/BR24 -> 0.26746382 | ... BX7: =BX25/BX24 -> 0.25
B8: SBC % of Rev | F8: =F32/F17 -> 0.0026013021 | G8: =G32/G17 -> 0.001510024 | H8: =H32/H17 -> 0.0018244392 | I8: =I32/I17 -> 0.0032190218 | J8: =J32/J17 -> 0.0023795717 | K8: =K32/K17 -> 0.0021525865 | L8: =L32/L17 -> 0.0016309313 | M8: =M32/M17 -> 0.0012866859 | ... AS8: =AS32/AS17 -> 0 | AT8: 0 | AU8: 0 | AV8: 0 | AW8: 0 | AX8: 0 | AY8: 0 | AZ8: 0 | BA8: 0 | BB8: 0 | BC8: 0 | BD8: 0 | BE8: 0 | BF8: 0 | BG8: 0 | BH8: 0 | BI8: 0 | BK8: =BK32/BK17 -> 0.002266486 | BL8: =BL32/BL17 -> 0.0018322406 | BM8: =BM32/BM17 -> 0.0012120127 | BN8: =BN32/BN17 -> 0.00042369817 | BO8: =BO32/BO17 -> 0 | BP8: =BP32/BP17 -> 0 | BQ8: =BQ32/BQ17 -> 0 | BR8: =BR32/BR17 -> 0 | ... BX8: =BX32/BX17 -> 0
B9: D&A % of Rev | F9: =F33/F17 -> 0.03899395 | G9: =G33/G17 -> 0.033246706 | H9: =H33/H17 -> 0.036579477 | I9: =I33/I17 -> 0.03949451 | J9: =J33/J17 -> 0.040407669 | K9: =K33/K17 -> 0.035975647 | L9: =L33/L17 -> 0.037200028 | M9: =M33/M17 -> 0.043109748 | ... AS9: =AS33/AS17 -> 0.029043577 | AT9: =AP9 -> 0.033780871 | AU9: =AQ9 -> 0.029514653 | AV9: =AR9 -> 0.029172009 | AW9: =AS9 -> 0.029043577 | AX9: =AT9 -> 0.033780871 | AY9: =AU9 -> 0.029514653 | AZ9: =AV9 -> 0.029172009 | BA9: =AW9 -> 0.029043577 | ... BI9: =BE9 -> 0.029043577 | BK9: =BK33/BK17 -> 0.036947778 | BL9: =BL33/BL17 -> 0.039050408 | BM9: =BM33/BM17 -> 0.040484598 | BN9: =BN33/BN17 -> 0.037276323 | BO9: =BO33/BO17 -> 0.035750796 | BP9: =BP33/BP17 -> 0.032459875 | BQ9: =BQ33/BQ17 -> 0.027671535 | BR9: =BR33/BR17 -> 0.026595999 | ... BX9: =BX33/BX17 -> 0.030317214
B10: Change in NWC % of Rev | F10: =F64/F17 -> -0.072414366 | G10: =G64/G17 -> 0.0088078783 | H10: =H64/H17 -> 0.0097405504 | I10: =I64/I17 -> -0.042424783 | J10: =J64/J17 -> -0.0011713038 | K10: =K64/K17 -> 0.0018199063 | L10: =L64/L17 -> -0.032074121 | M10: =M64/M17 -> 0.015465094 | ... AS10: =AS64/AS17 -> -0.013792365 | AT10: =AP10 -> -0.024698461 | AU10: =AQ10 -> 0.0038630701 | AV10: =AR10 -> 0.027175522 | AW10: =AS10 -> -0.013792365 | AX10: =AT10 -> -0.024698461 | AY10: =AU10 -> 0.0038630701 | AZ10: =AV10 -> 0.027175522 | BA10: =AW10 -> -0.013792365 | ... BI10: =BE10 -> -0.013792365 | BK10: =BK64/BK17 -> -0.020695229 | BL10: =BL64/BL17 -> -0.0043382147 | BM10: =BM64/BM17 -> -0.010196387 | BN10: =BN64/BN17 -> -0.0049068185 | BO10: =BO64/BO17 -> 0.01559066 | BP10: =BP64/BP17 -> 0.0041113025 | BQ10: =BQ64/BQ17 -> -0.012326323 | BR10: =BR64/BR17 -> -0.00089451864 | ... BX10: =BX64/BX17 -> -0.0015017027
B11: Adj. EBITDA Margins % | F11: =IF(F17=0,0,F35/F17) -> 0.061422386 | G11: =IF(G17=0,0,G35/G17) -> 0.09988886 | H11: =IF(H17=0,0,H35/H17) -> 0.085282229 | I11: =IF(I17=0,0,I35/I17) -> 0.067573316 | J11: =IF(J17=0,0,J35/J17) -> 0.058506276 | K11: =IF(K17=0,0,K35/K17) -> 0.078591215 | L11: =IF(L17=0,0,L35/L17) -> 0.069909834 | M11: =IF(M17=0,0,M35/M17) -> 0.043622114 | ... BI11: =IF(BI17=0,0,BI35/BI17) -> 0.11630295 | BK11: =BK35/BK17 -> 0.079721761 | BL11: =BL35/BL17 -> 0.063127419 | BM11: =BM35/BM17 -> 0.054214976 | BN11: =BN35/BN17 -> 0.075149967 | BO11: =BO35/BO17 -> 0.098334311 | BP11: =BP35/BP17 -> 0.11140893 | BQ11: =BQ35/BQ17 -> 0.13105026 | BR11: =BR35/BR17 -> 0.1520046 | ... BX11: =BX35/BX17 -> 0.11688211
B12: Gross Profit Margin % | F12: =F19/F17 -> 0.38995229 | G12: =G19/G17 -> 0.38042966 | H12: =H19/H17 -> 0.38537009 | I12: =I19/I17 -> 0.38610081 | J12: =J19/J17 -> 0.38352805 | K12: =K19/K17 -> 0.35506816 | L12: =L19/L17 -> 0.35295899 | M12: =M19/M17 -> 0.3404736 | ... BI12: =BI19/BI17 -> 0.3751909 | BK12: =BK41/BK17 -> 0.38515753 | BL12: =BL41/BL17 -> 0.35639809 | BM12: =BM41/BM17 -> 0.33634369 | BN12: =BN41/BN17 -> 0.34610692 | BO12: =BO41/BO17 -> 0.35326201 | BP12: =BP41/BP17 -> 0.351301 | BQ12: =BQ41/BQ17 -> 0.36735523 | BR12: =BR41/BR17 -> 0.39055703 | ... BX12: =BX41/BX17 -> 0.36492837
B13: SD&A % of Rev | J13: =J20/F20-1 -> 0.37545195 | K13: =K20/G20-1 -> 0.38832174 | L13: =L20/H20-1 -> 0.30204705 | M13: =M20/I20-1 -> 0.26410663 | N13: =N20/J20-1 -> 0.18286 | O13: =O20/K20-1 -> 0.046658421 | P13: =P20/L20-1 -> -0.015719119 | Q13: =Q20/M20-1 -> -0.042844578 | ... AS13: =AS20/AO20-1 -> 0.068881816 | AT13: 0.035 | AU13: 0.035 | AV13: 0.035 | AW13: 0.035 | AX13: 0.035 | AY13: 0.035 | AZ13: 0.035 | BA13: 0.035 | BB13: 0.035 | BC13: 0.035 | BD13: 0.035 | BE13: 0.035 | BF13: 0.035 | BG13: 0.035 | BH13: 0.035 | BI13: 0.035 | BK13: =BK20/BK17 -> 0.34465003 | BL13: =BL20/BL17 -> 0.33415332 | BM13: =BM20/BM17 -> 0.32382532 | BN13: =BN20/BN17 -> 0.30865697 | BO13: =BO20/BO17 -> 0.2906785 | BP13: =BP20/BP17 -> 0.27235195 | BQ13: =BQ20/BQ17 -> 0.26397651 | BR13: =BR20/BR17 -> 0.26514843 | ... BX13: =BX20/BX17 -> 0.27836348
B14: Interest Rate % | F14: =F22*4/F55 -> 0.045994689 | G14: =G22*4/G55 -> 0.044474977 | H14: =H22*4/H55 -> 0.038834416 | I14: =I22*4/I55 -> 0.036419362 | J14: =J22*4/J55 -> 0.036103629 | K14: =K22*4/K55 -> 0.037100081 | L14: =L22*4/L55 -> 0.036540521 | M14: =M22*4/M55 -> 0.039813096 | ... AS14: =AS22*4/AS55 -> 0.036113673 | AT14: 0.06 | AU14: 0.06 | AV14: 0.06 | AW14: 0.06 | AX14: 0.06 | AY14: 0.06 | AZ14: 0.06 | BA14: 0.06 | BB14: 0.06 | BC14: 0.06 | BD14: 0.06 | BE14: 0.06 | BF14: 0.06 | BG14: 0.06 | BH14: 0.06 | BI14: 0.06 | BK14: =BK22/BK58 -> 0.043182859 | BL14: =BL22/BL58 -> 0.038297832 | BM14: =BM22/BM58 -> 0.042593573 | BN14: =BN22/BN58 -> 0.042014398 | BO14: =BO22/BO58 -> 0.038672736 | BP14: =BP22/BP58 -> 0.043718182 | BQ14: =BQ22/BQ58 -> 0.049323719 | BR14: =BR22/BR58 -> -0.0080125687 | ... BX14: =BX22/BX58 -> 0.06376884
A16: x | B16: GAAP P&L
B17: Revenue | F17: ='Canalyst HC - Q'!C401 -> 625.456 | G17: ='Canalyst HC - Q'!D401 -> 840.384 | H17: ='Canalyst HC - Q'!E401 -> 849.028 | I17: ='Canalyst HC - Q'!F401 -> 841.56 | J17: ='Canalyst HC - Q'!G401 -> 865.702 | K17: ='Canalyst HC - Q'!H401 -> 1169.291 | L17: ='Canalyst HC - Q'!I401 -> 1162.526 | M17: ='Canalyst HC - Q'!J401 -> 1126.149 | ... AS17: ='Canalyst HC - Q'!AP401 -> 1904.242 | AT17: ='Segment Build'!AT8 -> 1758.8331 | AU17: ='Segment Build'!AU8 -> 1859.8329 | AV17: ='Segment Build'!AV8 -> 1893.0011 | AW17: ='Segment Build'!AW8 -> 1909.1116 | AX17: ='Segment Build'!AX8 -> 1811.9216 | AY17: ='Segment Build'!AY8 -> 1915.9691 | AZ17: ='Segment Build'!AZ8 -> 1950.1364 | BA17: ='Segment Build'!BA8 -> 1966.7323 | ... BI17: ='Segment Build'!BI8 -> 2087.2437 | BK17: =SUMIF($F$1:$BI$1,BK$1,$F17:$BI17) -> 3156.428 | BL17: =SUMIF($F$1:$BI$1,BL$1,$F17:$BI17) -> 4323.668 | BM17: =SUMIF($F$1:$BI$1,BM$1,$F17:$BI17) -> 4625.364 | BN17: =SUMIF($F$1:$BI$1,BN$1,$F17:$BI17) -> 4826.549 | BO17: =SUMIF($F$1:$BI$1,BO$1,$F17:$BI17) -> 5007.357 | BP17: =SUMIF($F$1:$BI$1,BP$1,$F17:$BI17) -> 5562.714 | BQ17: =SUMIF($F$1:$BI$1,BQ$1,$F17:$BI17) -> 6200.957 | BR17: =SUMIF($F$1:$BI$1,BR$1,$F17:$BI17) -> 6653.858 | ... BX17: =SUMIF($F$1:$BI$1,BX$1,$F17:$BI17) -> 8113.2062
C18: COGS | F18: ='Canalyst HC - Q'!C404 -> 381.558 | G18: ='Canalyst HC - Q'!D404 -> 520.677 | H18: ='Canalyst HC - Q'!E404 -> 521.838 | I18: ='Canalyst HC - Q'!F404 -> 516.633 | J18: ='Canalyst HC - Q'!G404 -> 533.681 | K18: ='Canalyst HC - Q'!H404 -> 754.113 | L18: ='Canalyst HC - Q'!I404 -> 752.202 | M18: ='Canalyst HC - Q'!J404 -> 742.725 | ... AS18: ='Canalyst HC - Q'!AP404 -> 1149.996 | AT18: ='COGS Sensitivity'!AT7 -> 1129.9912 | AU18: ='COGS Sensitivity'!AU7 -> 1196.7167 | AV18: ='COGS Sensitivity'!AV7 -> 1206.5883 | AW18: ='COGS Sensitivity'!AW7 -> 1203.4099 | AX18: ='COGS Sensitivity'!AX7 -> 1177.6653 | AY18: ='COGS Sensitivity'!AY7 -> 1222.2684 | AZ18: ='COGS Sensitivity'!AZ7 -> 1230.3595 | BA18: ='COGS Sensitivity'!BA7 -> 1223.1996 | ... BI18: ='COGS Sensitivity'!BI7 -> 1304.1289 | BK18: =SUMIF($F$1:$BI$1,BK$1,$F18:$BI18) -> 1940.706 | BL18: =SUMIF($F$1:$BI$1,BL$1,$F18:$BI18) -> 2782.721 | BM18: =SUMIF($F$1:$BI$1,BM$1,$F18:$BI18) -> 3069.652 | BN18: =SUMIF($F$1:$BI$1,BN$1,$F18:$BI18) -> 3156.047 | BO18: =SUMIF($F$1:$BI$1,BO$1,$F18:$BI18) -> 3238.448 | BP18: =SUMIF($F$1:$BI$1,BP$1,$F18:$BI18) -> 3608.527 | BQ18: =SUMIF($F$1:$BI$1,BQ$1,$F18:$BI18) -> 3923.003 | BR18: =SUMIF($F$1:$BI$1,BR$1,$F18:$BI18) -> 4055.147 | ... BX18: =SUMIF($F$1:$BI$1,BX$1,$F18:$BI18) -> 5152.4671
B19: Gross Profit | F19: =F17-F18 -> 243.898 | G19: =G17-G18 -> 319.707 | H19: =H17-H18 -> 327.19 | I19: =I17-I18 -> 324.927 | J19: =J17-J18 -> 332.021 | K19: =K17-K18 -> 415.178 | L19: =L17-L18 -> 410.324 | M19: =M17-M18 -> 383.424 | ... BI19: =BI17-BI18 -> 783.11485 | BK19: =SUMIF($F$1:$BI$1,BK$1,$F19:$BI19) -> 1215.722 | BL19: =SUMIF($F$1:$BI$1,BL$1,$F19:$BI19) -> 1540.947 | BM19: =SUMIF($F$1:$BI$1,BM$1,$F19:$BI19) -> 1555.712 | BN19: =SUMIF($F$1:$BI$1,BN$1,$F19:$BI19) -> 1670.502 | BO19: =SUMIF($F$1:$BI$1,BO$1,$F19:$BI19) -> 1768.909 | BP19: =SUMIF($F$1:$BI$1,BP$1,$F19:$BI19) -> 1954.187 | BQ19: =SUMIF($F$1:$BI$1,BQ$1,$F19:$BI19) -> 2277.954 | BR19: =SUMIF($F$1:$BI$1,BR$1,$F19:$BI19) -> 2598.711 | ... BX19: =SUMIF($F$1:$BI$1,BX$1,$F19:$BI19) -> 2960.7391
C20: SD&A | F20: ='Canalyst HC - Q'!C407 -> 231.497 | G20: ='Canalyst HC - Q'!D407 -> 264.971 | H20: ='Canalyst HC - Q'!E407 -> 287.389 | I20: ='Canalyst HC - Q'!F407 -> 304.006 | J20: ='Canalyst HC - Q'!G407 -> 318.413 | K20: ='Canalyst HC - Q'!H407 -> 367.865 | L20: ='Canalyst HC - Q'!I407 -> 374.194 | M20: ='Canalyst HC - Q'!J407 -> 384.296 | ... AS20: ='Canalyst HC - Q'!AP407 -> 512.128 | AT20: =AP20*(1+AT13)+12 -> 464.58894 | AU20: =AQ20*(1+AU13)+12 -> 498.87642 | AV20: =AR20*(1+AV13)+12 -> 531.44787 | AW20: =AS20*(1+AW13)+12 -> 542.05248 | AX20: =AT20*(1+AX13) -> 480.84955 | AY20: =AU20*(1+AY13) -> 516.33709 | AZ20: =AV20*(1+AZ13) -> 550.04855 | BA20: =AW20*(1+BA13) -> 561.02432 | BB20: =AX20*(1+BB13) -> 497.67929 | BC20: =AY20*(1+BC13) -> 534.40889 | BD20: =AZ20*(1+BD13) -> 569.30024 | BE20: =BA20*(1+BE13) -> 580.66017 | ... BI20: =BE20*(1+BI13) -> 600.98327 | BK20: =SUMIF($F$1:$BI$1,BK$1,$F20:$BI20) -> 1087.863 | BL20: =SUMIF($F$1:$BI$1,BL$1,$F20:$BI20) -> 1444.768 | BM20: =SUMIF($F$1:$BI$1,BM$1,$F20:$BI20) -> 1497.81 | BN20: =SUMIF($F$1:$BI$1,BN$1,$F20:$BI20) -> 1489.748 | BO20: =SUMIF($F$1:$BI$1,BO$1,$F20:$BI20) -> 1455.531 | BP20: =SUMIF($F$1:$BI$1,BP$1,$F20:$BI20) -> 1515.016 | BQ20: =SUMIF($F$1:$BI$1,BQ$1,$F20:$BI20) -> 1636.907 | BR20: =SUMIF($F$1:$BI$1,BR$1,$F20:$BI20) -> 1764.26 | ... BX20: =SUMIF($F$1:$BI$1,BX$1,$F20:$BI20) -> 2258.4203
B21: EBIT | F21: =F19-F20 -> 12.401 | G21: =G19-G20 -> 54.736 | H21: =H19-H20 -> 39.801 | I21: =I19-I20 -> 20.921 | J21: =J19-J20 -> 13.608 | K21: =K19-K20 -> 47.313 | L21: =L19-L20 -> 36.13 | M21: =M19-M20 -> -0.872 | ... BI21: =BI19-BI20 -> 182.13158 | BK21: =SUMIF($F$1:$BI$1,BK$1,$F21:$BI21) -> 127.859 | BL21: =SUMIF($F$1:$BI$1,BL$1,$F21:$BI21) -> 96.179 | BM21: =SUMIF($F$1:$BI$1,BM$1,$F21:$BI21) -> 57.902 | BN21: =SUMIF($F$1:$BI$1,BN$1,$F21:$BI21) -> 180.754 | BO21: =SUMIF($F$1:$BI$1,BO$1,$F21:$BI21) -> 313.378 | BP21: =SUMIF($F$1:$BI$1,BP$1,$F21:$BI21) -> 439.171 | BQ21: =SUMIF($F$1:$BI$1,BQ$1,$F21:$BI21) -> 641.047 | BR21: =SUMIF($F$1:$BI$1,BR$1,$F21:$BI21) -> 834.451 | ... BX21: =SUMIF($F$1:$BI$1,BX$1,$F21:$BI21) -> 702.31882
C22: Interest Expense / (Income) | F22: ='Canalyst HC - Q'!C419 -> 9.361 | G22: ='Canalyst HC - Q'!D419 -> 9.808 | H22: ='Canalyst HC - Q'!E419 -> 8.452 | I22: ='Canalyst HC - Q'!F419 -> 8.704 | J22: ='Canalyst HC - Q'!G419 -> 9.47 | K22: ='Canalyst HC - Q'!H419 -> 10.44 | L22: ='Canalyst HC - Q'!I419 -> 10.697 | M22: ='Canalyst HC - Q'!J419 -> 11.262 | ... AS22: ='Canalyst HC - Q'!AP419 -> 25.169 | AT22: =AT14*AS55/4 -> 41.816295 | AU22: =AU14*AT55/4 -> 41.816295 | AV22: =AV14*AU55/4 -> 41.816295 | AW22: =AW14*AV55/4 -> 41.816295 | AX22: =AX14*AW55/4 -> 41.816295 | AY22: =AY14*AX55/4 -> 41.816295 | AZ22: =AZ14*AY55/4 -> 41.816295 | BA22: =BA14*AZ55/4 -> 41.816295 | ... BI22: =BI14*BH55/4 -> 41.816295 | BK22: =SUMIF($F$1:$BI$1,BK$1,$F22:$BI22) -> 36.325 | BL22: =SUMIF($F$1:$BI$1,BL$1,$F22:$BI22) -> 41.869 | BM22: =SUMIF($F$1:$BI$1,BM$1,$F22:$BI22) -> 50.506 | BN22: =SUMIF($F$1:$BI$1,BN$1,$F22:$BI22) -> 45.99 | BO22: =SUMIF($F$1:$BI$1,BO$1,$F22:$BI22) -> 36.735 | BP22: =SUMIF($F$1:$BI$1,BP$1,$F22:$BI22) -> 33.449 | BQ22: =SUMIF($F$1:$BI$1,BQ$1,$F22:$BI22) -> 24.792 | BR22: =SUMIF($F$1:$BI$1,BR$1,$F22:$BI22) -> -0.918 | ... BX22: =SUMIF($F$1:$BI$1,BX$1,$F22:$BI22) -> 167.26518
C23: Other | F23: ='Canalyst HC - Q'!C420+'Canalyst HC - Q'!C421 -> 17.151 | G23: ='Canalyst HC - Q'!D420+'Canalyst HC - Q'!D421 -> 16.966 | H23: ='Canalyst HC - Q'!E420+'Canalyst HC - Q'!E421 -> -7.325 | I23: ='Canalyst HC - Q'!F420+'Canalyst HC - Q'!F421 -> -27.97 | J23: ='Canalyst HC - Q'!G420+'Canalyst HC - Q'!G421 -> 12.246 | K23: ='Canalyst HC - Q'!H420+'Canalyst HC - Q'!H421 -> 25.549 | L23: ='Canalyst HC - Q'!I420+'Canalyst HC - Q'!I421 -> -5.226 | M23: ='Canalyst HC - Q'!J420+'Canalyst HC - Q'!J421 -> -41.265 | ... AS23: ='Canalyst HC - Q'!AP420+'Canalyst HC - Q'!AP421 -> 28.726 | AT23: =AP23 -> 43.473 | AU23: =AQ23 -> 13.144 | AV23: =AR23 -> 49.717 | AW23: =AS23 -> 28.726 | AX23: =AT23 -> 43.473 | AY23: =AU23 -> 13.144 | AZ23: =AV23 -> 49.717 | BA23: =AW23 -> 28.726 | ... BI23: =BE23 -> 28.726 | BK23: =SUMIF($F$1:$BI$1,BK$1,$F23:$BI23) -> -1.178 | BL23: =SUMIF($F$1:$BI$1,BL$1,$F23:$BI23) -> -8.696 | BM23: =SUMIF($F$1:$BI$1,BM$1,$F23:$BI23) -> 20.683 | BN23: =SUMIF($F$1:$BI$1,BN$1,$F23:$BI23) -> 100.539 | BO23: =SUMIF($F$1:$BI$1,BO$1,$F23:$BI23) -> 35.603 | BP23: =SUMIF($F$1:$BI$1,BP$1,$F23:$BI23) -> 150.573 | BQ23: =SUMIF($F$1:$BI$1,BQ$1,$F23:$BI23) -> 41.168 | BR23: =SUMIF($F$1:$BI$1,BR$1,$F23:$BI23) -> 277.888 | ... BX23: =SUMIF($F$1:$BI$1,BX$1,$F23:$BI23) -> 135.06
B24: EBT | F24: =F21-SUM(F22:F23) -> -14.111 | G24: =G21-SUM(G22:G23) -> 27.962 | H24: =H21-SUM(H22:H23) -> 38.674 | I24: =I21-SUM(I22:I23) -> 40.187 | J24: =J21-SUM(J22:J23) -> -8.108 | K24: =K21-SUM(K22:K23) -> 11.324 | L24: =L21-SUM(L22:L23) -> 30.659 | M24: =M21-SUM(M22:M23) -> 29.131 | ... BI24: =BI21-SUM(BI22:BI23) -> 111.58928 | BK24: =SUMIF($F$1:$BI$1,BK$1,$F24:$BI24) -> 92.712 | BL24: =SUMIF($F$1:$BI$1,BL$1,$F24:$BI24) -> 63.006 | BM24: =SUMIF($F$1:$BI$1,BM$1,$F24:$BI24) -> -13.287 | BN24: =SUMIF($F$1:$BI$1,BN$1,$F24:$BI24) -> 34.225 | BO24: =SUMIF($F$1:$BI$1,BO$1,$F24:$BI24) -> 241.04 | BP24: =SUMIF($F$1:$BI$1,BP$1,$F24:$BI24) -> 255.149 | BQ24: =SUMIF($F$1:$BI$1,BQ$1,$F24:$BI24) -> 575.087 | BR24: =SUMIF($F$1:$BI$1,BR$1,$F24:$BI24) -> 557.481 | ... BX24: =SUMIF($F$1:$BI$1,BX$1,$F24:$BI24) -> 399.99364
C25: Taxes | F25: ='Canalyst HC - Q'!C424+'Canalyst HC - Q'!C425 -> -5.078 | G25: ='Canalyst HC - Q'!D424+'Canalyst HC - Q'!D425 -> 10.638 | H25: ='Canalyst HC - Q'!E424+'Canalyst HC - Q'!E425 -> 13.121 | I25: ='Canalyst HC - Q'!F424+'Canalyst HC - Q'!F425 -> 17.368 | J25: ='Canalyst HC - Q'!G424+'Canalyst HC - Q'!G425 -> -3.691 | K25: ='Canalyst HC - Q'!H424+'Canalyst HC - Q'!H425 -> 3.743 | L25: ='Canalyst HC - Q'!I424+'Canalyst HC - Q'!I425 -> 11.748 | M25: ='Canalyst HC - Q'!J424+'Canalyst HC - Q'!J425 -> -51.641 | ... AS25: ='Canalyst HC - Q'!AP424+'Canalyst HC - Q'!AP425 -> 50.973 | AT25: =AT24*AT7 -> 19.740916 | AU25: =AU24*AU7 -> 27.319891 | AV25: =AV24*AV7 -> 15.857912 | AW25: =AW24*AW7 -> 23.276717 | AX25: =AX24*AX7 -> 17.029354 | AY25: =AY24*AY7 -> 30.60084 | AZ25: =AZ24*AZ7 -> 19.548766 | BA25: =BA24*BA7 -> 27.991521 | ... BI25: =BI24*BI7 -> 27.89732 | BK25: =SUMIF($F$1:$BI$1,BK$1,$F25:$BI25) -> 36.049 | BL25: =SUMIF($F$1:$BI$1,BL$1,$F25:$BI25) -> -39.841 | BM25: =SUMIF($F$1:$BI$1,BM$1,$F25:$BI25) -> 1.869 | BN25: =SUMIF($F$1:$BI$1,BN$1,$F25:$BI25) -> 15.665 | BO25: =SUMIF($F$1:$BI$1,BO$1,$F25:$BI25) -> 58.943 | BP25: =SUMIF($F$1:$BI$1,BP$1,$F25:$BI25) -> 65.569 | BQ25: =SUMIF($F$1:$BI$1,BQ$1,$F25:$BI25) -> 144.929 | BR25: =SUMIF($F$1:$BI$1,BR$1,$F25:$BI25) -> 149.106 | ... BX25: =SUMIF($F$1:$BI$1,BX$1,$F25:$BI25) -> 99.99841
B26: Net Income | F26: ='Canalyst HC - Q'!C426 -> -9.033 | G26: ='Canalyst HC - Q'!D426 -> 17.324 | H26: ='Canalyst HC - Q'!E426 -> 25.553 | I26: ='Canalyst HC - Q'!F426 -> 22.819 | J26: ='Canalyst HC - Q'!G426 -> -4.417 | K26: ='Canalyst HC - Q'!H426 -> 7.581 | L26: ='Canalyst HC - Q'!I426 -> 18.911 | M26: ='Canalyst HC - Q'!J426 -> 80.772 | ... AS26: ='Canalyst HC - Q'!AP426 -> 137.25 | AT26: =AT24-AT25 -> 59.222747 | AU26: =AU24-AU25 -> 81.959673 | AV26: =AV24-AV25 -> 47.573735 | AW26: =AW24-AW25 -> 69.830151 | AX26: =AX24-AX25 -> 51.088062 | AY26: =AY24-AY25 -> 91.80252 | AZ26: =AZ24-AZ25 -> 58.646299 | BA26: =BA24-BA25 -> 83.974563 | ... BI26: =BI24-BI25 -> 83.691961 | BK26: =SUMIF($F$1:$BI$1,BK$1,$F26:$BI26) -> 56.663 | BL26: =SUMIF($F$1:$BI$1,BL$1,$F26:$BI26) -> 102.847 | BM26: =SUMIF($F$1:$BI$1,BM$1,$F26:$BI26) -> -15.156 | BN26: =SUMIF($F$1:$BI$1,BN$1,$F26:$BI26) -> 18.56 | BO26: =SUMIF($F$1:$BI$1,BO$1,$F26:$BI26) -> 182.097 | BP26: =SUMIF($F$1:$BI$1,BP$1,$F26:$BI26) -> 189.58 | BQ26: =SUMIF($F$1:$BI$1,BQ$1,$F26:$BI26) -> 430.158 | BR26: =SUMIF($F$1:$BI$1,BR$1,$F26:$BI26) -> 408.375 | ... BX26: =SUMIF($F$1:$BI$1,BX$1,$F26:$BI26) -> 299.99523
C27: discontinued operations | F27: ='Canalyst HC - Q'!C427 -> 0 | G27: ='Canalyst HC - Q'!D427 -> 0 | H27: ='Canalyst HC - Q'!E427 -> 0 | I27: ='Canalyst HC - Q'!F427 -> 0 | J27: ='Canalyst HC - Q'!G427 -> 0 | K27: ='Canalyst HC - Q'!H427 -> 0 | L27: ='Canalyst HC - Q'!I427 -> 0 | M27: ='Canalyst HC - Q'!J427 -> 0 | ... AS27: ='Canalyst HC - Q'!AP427 -> 0 | AT27: =0 -> 0 | AU27: =0 -> 0 | AV27: =0 -> 0 | AW27: =0 -> 0 | AX27: =0 -> 0 | AY27: =0 -> 0 | AZ27: =0 -> 0 | BA27: =0 -> 0 | ... BI27: =0 -> 0 | BK27: =SUMIF($F$1:$BI$1,BK$1,$F27:$BI27) -> 0 | BL27: =SUMIF($F$1:$BI$1,BL$1,$F27:$BI27) -> 0 | BM27: =SUMIF($F$1:$BI$1,BM$1,$F27:$BI27) -> 0 | BN27: =SUMIF($F$1:$BI$1,BN$1,$F27:$BI27) -> 0 | BO27: =SUMIF($F$1:$BI$1,BO$1,$F27:$BI27) -> 0 | BP27: =SUMIF($F$1:$BI$1,BP$1,$F27:$BI27) -> 0 | BQ27: =SUMIF($F$1:$BI$1,BQ$1,$F27:$BI27) -> 0 | BR27: =SUMIF($F$1:$BI$1,BR$1,$F27:$BI27) -> 0 | ... BX27: =SUMIF($F$1:$BI$1,BX$1,$F27:$BI27) -> 0
C28: NCI | F28: ='Canalyst HC - Q'!C428+'Canalyst HC - Q'!C429 -> -1.322 | G28: ='Canalyst HC - Q'!D428+'Canalyst HC - Q'!D429 -> 5.322 | H28: ='Canalyst HC - Q'!E428+'Canalyst HC - Q'!E429 -> 7.808 | I28: ='Canalyst HC - Q'!F428+'Canalyst HC - Q'!F429 -> 6.386 | J28: ='Canalyst HC - Q'!G428+'Canalyst HC - Q'!G429 -> -0.548 | K28: ='Canalyst HC - Q'!H428+'Canalyst HC - Q'!H429 -> 2.724 | L28: ='Canalyst HC - Q'!I428+'Canalyst HC - Q'!I429 -> 5.663 | M28: ='Canalyst HC - Q'!J428+'Canalyst HC - Q'!J429 -> 21.113 | ... AS28: ='Canalyst HC - Q'!AP428+'Canalyst HC - Q'!AP429 -> 18.05 | AT28: =0 -> 0 | AU28: =0 -> 0 | AV28: =0 -> 0 | AW28: =0 -> 0 | AX28: =0 -> 0 | AY28: =0 -> 0 | AZ28: =0 -> 0 | BA28: =0 -> 0 | ... BI28: =0 -> 0 | BK28: =SUMIF($F$1:$BI$1,BK$1,$F28:$BI28) -> 18.194 | BL28: =SUMIF($F$1:$BI$1,BL$1,$F28:$BI28) -> 28.952 | BM28: =SUMIF($F$1:$BI$1,BM$1,$F28:$BI28) -> 0.068 | BN28: =SUMIF($F$1:$BI$1,BN$1,$F28:$BI28) -> 9.89 | BO28: =SUMIF($F$1:$BI$1,BO$1,$F28:$BI28) -> 50.681 | BP28: =SUMIF($F$1:$BI$1,BP$1,$F28:$BI28) -> 45.146 | BQ28: =SUMIF($F$1:$BI$1,BQ$1,$F28:$BI28) -> 57.737 | BR28: =SUMIF($F$1:$BI$1,BR$1,$F28:$BI28) -> 43.782 | ... BX28: =SUMIF($F$1:$BI$1,BX$1,$F28:$BI28) -> 0
B29: Net Income to Common | F29: =F26-SUM(F27:F28) -> -7.711 | G29: =G26-SUM(G27:G28) -> 12.002 | H29: =H26-SUM(H27:H28) -> 17.745 | I29: =I26-SUM(I27:I28) -> 16.433 | J29: =J26-SUM(J27:J28) -> -3.869 | K29: =K26-SUM(K27:K28) -> 4.857 | L29: =L26-SUM(L27:L28) -> 13.248 | M29: =M26-SUM(M27:M28) -> 59.659 | ... BI29: =BI26-SUM(BI27:BI28) -> 83.691961 | BK29: =SUMIF($F$1:$BI$1,BK$1,$F29:$BI29) -> 38.469 | BL29: =SUMIF($F$1:$BI$1,BL$1,$F29:$BI29) -> 73.895 | BM29: =SUMIF($F$1:$BI$1,BM$1,$F29:$BI29) -> -15.224 | BN29: =SUMIF($F$1:$BI$1,BN$1,$F29:$BI29) -> 8.67 | BO29: =SUMIF($F$1:$BI$1,BO$1,$F29:$BI29) -> 131.416 | BP29: =SUMIF($F$1:$BI$1,BP$1,$F29:$BI29) -> 144.434 | BQ29: =SUMIF($F$1:$BI$1,BQ$1,$F29:$BI29) -> 372.421 | BR29: =SUMIF($F$1:$BI$1,BR$1,$F29:$BI29) -> 364.593 | ... BX29: =SUMIF($F$1:$BI$1,BX$1,$F29:$BI29) -> 299.99523
A31: x | B31: Adjustments / D&A / EBITDA
C32: SBC | F32: ='Canalyst HC - Q'!C414 -> 1.627 | G32: ='Canalyst HC - Q'!D414 -> 1.269 | H32: ='Canalyst HC - Q'!E414 -> 1.549 | I32: ='Canalyst HC - Q'!F414 -> 2.709 | J32: ='Canalyst HC - Q'!G414 -> 2.06 | K32: ='Canalyst HC - Q'!H414 -> 2.517 | L32: ='Canalyst HC - Q'!I414 -> 1.896 | M32: ='Canalyst HC - Q'!J414 -> 1.449 | ... AS32: ='Canalyst HC - Q'!AP414 -> 0 | AT32: =AT8*AT17 -> 0 | AU32: =AU8*AU17 -> 0 | AV32: =AV8*AV17 -> 0 | AW32: =AW8*AW17 -> 0 | AX32: =AX8*AX17 -> 0 | AY32: =AY8*AY17 -> 0 | AZ32: =AZ8*AZ17 -> 0 | BA32: =BA8*BA17 -> 0 | ... BI32: =BI8*BI17 -> 0 | BK32: =SUMIF($F$1:$BI$1,BK$1,$F32:$BI32) -> 7.154 | BL32: =SUMIF($F$1:$BI$1,BL$1,$F32:$BI32) -> 7.922 | BM32: =SUMIF($F$1:$BI$1,BM$1,$F32:$BI32) -> 5.606 | BN32: =SUMIF($F$1:$BI$1,BN$1,$F32:$BI32) -> 2.045 | BO32: =SUMIF($F$1:$BI$1,BO$1,$F32:$BI32) -> 0 | BP32: =SUMIF($F$1:$BI$1,BP$1,$F32:$BI32) -> 0 | BQ32: =SUMIF($F$1:$BI$1,BQ$1,$F32:$BI32) -> 0 | BR32: =SUMIF($F$1:$BI$1,BR$1,$F32:$BI32) -> 0 | ... BX32: =SUMIF($F$1:$BI$1,BX$1,$F32:$BI32) -> 0
C33: D&A | F33: ='Canalyst HC - Q'!C412+'Canalyst HC - Q'!C413 -> 24.389 | G33: ='Canalyst HC - Q'!D412+'Canalyst HC - Q'!D413 -> 27.94 | H33: ='Canalyst HC - Q'!E412+'Canalyst HC - Q'!E413 -> 31.057 | I33: ='Canalyst HC - Q'!F412+'Canalyst HC - Q'!F413 -> 33.237 | J33: ='Canalyst HC - Q'!G412+'Canalyst HC - Q'!G413 -> 34.981 | K33: ='Canalyst HC - Q'!H412+'Canalyst HC - Q'!H413 -> 42.066 | L33: ='Canalyst HC - Q'!I412+'Canalyst HC - Q'!I413 -> 43.246 | M33: ='Canalyst HC - Q'!J412+'Canalyst HC - Q'!J413 -> 48.548 | ... AS33: ='Canalyst HC - Q'!AP412+'Canalyst HC - Q'!AP413 -> 55.306 | AT33: =AT9*AT17 -> 59.414914 | AU33: =AU9*AU17 -> 54.892325 | AV33: =AV9*AV17 -> 55.222644 | AW33: =AW9*AW17 -> 55.447429 | AX33: =AX9*AX17 -> 61.208291 | AY33: =AY9*AY17 -> 56.549164 | AZ33: =AZ9*AZ17 -> 56.889395 | BA33: =BA9*BA17 -> 57.120942 | ... BI33: =BI9*BI17 -> 60.621024 | BK33: =SUMIF($F$1:$BI$1,BK$1,$F33:$BI33) -> 116.623 | BL33: =SUMIF($F$1:$BI$1,BL$1,$F33:$BI33) -> 168.841 | BM33: =SUMIF($F$1:$BI$1,BM$1,$F33:$BI33) -> 187.256 | BN33: =SUMIF($F$1:$BI$1,BN$1,$F33:$BI33) -> 179.916 | BO33: =SUMIF($F$1:$BI$1,BO$1,$F33:$BI33) -> 179.017 | BP33: =SUMIF($F$1:$BI$1,BP$1,$F33:$BI33) -> 180.565 | BQ33: =SUMIF($F$1:$BI$1,BQ$1,$F33:$BI33) -> 171.59 | BR33: =SUMIF($F$1:$BI$1,BR$1,$F33:$BI33) -> 176.966 | ... BX33: =SUMIF($F$1:$BI$1,BX$1,$F33:$BI33) -> 245.96981
C34: Other | F34: =F35-(F21+F33+F32) -> 0 | G34: =G35-(G21+G33+G32) -> 0 | H34: =H35-(H21+H33+H32) -> 0 | I34: =I35-(I21+I33+I32) -> 0 | J34: =J35-(J21+J33+J32) -> 0 | K34: =K35-(K21+K33+K32) -> 0 | L34: =L35-(L21+L33+L32) -> 0 | M34: =M35-(M21+M33+M32) -> 4.0500936e-13 | ... AS34: =AS35-(AS21+AS33+AS32) -> 6.8212103e-13 | AT34: 0 | AU34: 0 | AV34: 0 | AW34: 0 | AX34: 0 | AY34: 0 | AZ34: 0 | BA34: 0 | BB34: 0 | BC34: 0 | BD34: 0 | BE34: 0 | BF34: 0 | BG34: 0 | BH34: 0 | BI34: 0 | BK34: =SUMIF($F$1:$BI$1,BK$1,$F34:$BI34) -> 0 | BL34: =SUMIF($F$1:$BI$1,BL$1,$F34:$BI34) -> 4.0500936e-13 | BM34: =SUMIF($F$1:$BI$1,BM$1,$F34:$BI34) -> 4.0500936e-13 | BN34: =SUMIF($F$1:$BI$1,BN$1,$F34:$BI34) -> 0 | BO34: =SUMIF($F$1:$BI$1,BO$1,$F34:$BI34) -> 0 | BP34: =SUMIF($F$1:$BI$1,BP$1,$F34:$BI34) -> 0 | BQ34: =SUMIF($F$1:$BI$1,BQ$1,$F34:$BI34) -> 0 | BR34: =SUMIF($F$1:$BI$1,BR$1,$F34:$BI34) -> 2.8421709e-13 | ... BX34: =SUMIF($F$1:$BI$1,BX$1,$F34:$BI34) -> 0
B35: Adj. EBITDA | F35: ='Canalyst HC - Q'!C416 -> 38.417 | G35: ='Canalyst HC - Q'!D416 -> 83.945 | H35: ='Canalyst HC - Q'!E416 -> 72.407 | I35: ='Canalyst HC - Q'!F416 -> 56.867 | J35: ='Canalyst HC - Q'!G416 -> 50.649 | K35: ='Canalyst HC - Q'!H416 -> 91.896 | L35: ='Canalyst HC - Q'!I416 -> 81.272 | M35: ='Canalyst HC - Q'!J416 -> 49.125 | ... AS35: ='Canalyst HC - Q'!AP416 -> 297.424 | AT35: =AT21+AT33+AT32+AT34 -> 223.66787 | AU35: =AU21+AU33+AU32+AU34 -> 219.13218 | AV35: =AV21+AV33+AV32+AV34 -> 210.18759 | AW35: =AW21+AW33+AW32+AW34 -> 219.09659 | AX35: =AX21+AX33+AX32+AX34 -> 214.615 | AY35: =AY21+AY33+AY32+AY34 -> 233.91282 | AZ35: =AZ21+AZ33+AZ32+AZ34 -> 226.61776 | BA35: =BA21+BA33+BA32+BA34 -> 239.62932 | ... BI35: =BI21+BI33+BI32+BI34 -> 242.7526 | BK35: =SUMIF($F$1:$BI$1,BK$1,$F35:$BI35) -> 251.636 | BL35: =SUMIF($F$1:$BI$1,BL$1,$F35:$BI35) -> 272.942 | BM35: =SUMIF($F$1:$BI$1,BM$1,$F35:$BI35) -> 250.764 | BN35: =SUMIF($F$1:$BI$1,BN$1,$F35:$BI35) -> 362.715 | BO35: =SUMIF($F$1:$BI$1,BO$1,$F35:$BI35) -> 492.395 | BP35: =SUMIF($F$1:$BI$1,BP$1,$F35:$BI35) -> 619.736 | BQ35: =SUMIF($F$1:$BI$1,BQ$1,$F35:$BI35) -> 812.637 | BR35: =SUMIF($F$1:$BI$1,BR$1,$F35:$BI35) -> 1011.417 | ... BX35: =SUMIF($F$1:$BI$1,BX$1,$F35:$BI35) -> 948.28863
C36: MTM on acquisition related | F36: ='Canalyst HC - Q'!C382 -> 10.531 | G36: ='Canalyst HC - Q'!D382 -> 9.992 | H36: ='Canalyst HC - Q'!E382 -> -4.53 | I36: ='Canalyst HC - Q'!F382 -> -17.202 | J36: ='Canalyst HC - Q'!G382 -> 7.519 | K36: ='Canalyst HC - Q'!H382 -> 9.897 | L36: ='Canalyst HC - Q'!I382 -> -3.208 | M36: ='Canalyst HC - Q'!J382 -> -8.583 | ... AS36: ='Canalyst HC - Q'!AP382 -> 20.63 | AT36: =AP36 -> 32.174 | AU36: =AQ36 -> 9.275 | AV36: =AR36 -> 37.111 | AW36: =AS36 -> 20.63 | AX36: =AT36 -> 32.174 | AY36: =AU36 -> 9.275 | AZ36: =AV36 -> 37.111 | BA36: =AW36 -> 20.63 | ... BI36: =BE36 -> 20.63 | BK36: =SUMIF($F$1:$BI$1,BK$1,$F36:$BI36) -> -1.209 | BL36: =SUMIF($F$1:$BI$1,BL$1,$F36:$BI36) -> 5.625 | BM36: =SUMIF($F$1:$BI$1,BM$1,$F36:$BI36) -> 21.92 | BN36: =SUMIF($F$1:$BI$1,BN$1,$F36:$BI36) -> 69.591 | BO36: =SUMIF($F$1:$BI$1,BO$1,$F36:$BI36) -> 23.408 | BP36: =SUMIF($F$1:$BI$1,BP$1,$F36:$BI36) -> 109.731 | BQ36: =SUMIF($F$1:$BI$1,BQ$1,$F36:$BI36) -> 24.306 | BR36: =SUMIF($F$1:$BI$1,BR$1,$F36:$BI36) -> 119.834 | ... BX36: =SUMIF($F$1:$BI$1,BX$1,$F36:$BI36) -> 99.19
A38: x | B38: non-GAAP P&L
B39: Revenue | F39: =F17 -> 625.456 | G39: =G17 -> 840.384 | H39: =H17 -> 849.028 | I39: =I17 -> 841.56 | J39: =J17 -> 865.702 | K39: =K17 -> 1169.291 | L39: =L17 -> 1162.526 | M39: =M17 -> 1126.149 | ... BI39: =BI17 -> 2087.2437 | BK39: =SUMIF($F$1:$BI$1,BK$1,$F39:$BI39) -> 3156.428 | BL39: =SUMIF($F$1:$BI$1,BL$1,$F39:$BI39) -> 4323.668 | BM39: =SUMIF($F$1:$BI$1,BM$1,$F39:$BI39) -> 4625.364 | BN39: =SUMIF($F$1:$BI$1,BN$1,$F39:$BI39) -> 4826.549 | BO39: =SUMIF($F$1:$BI$1,BO$1,$F39:$BI39) -> 5007.357 | BP39: =SUMIF($F$1:$BI$1,BP$1,$F39:$BI39) -> 5562.714 | BQ39: =SUMIF($F$1:$BI$1,BQ$1,$F39:$BI39) -> 6200.957 | BR39: =SUMIF($F$1:$BI$1,BR$1,$F39:$BI39) -> 6653.858 | ... BX39: =SUMIF($F$1:$BI$1,BX$1,$F39:$BI39) -> 8113.2062
C40: COGS | F40: =F18 -> 381.558 | G40: =G18 -> 520.677 | H40: =H18 -> 521.838 | I40: =I18 -> 516.633 | J40: =J18 -> 533.681 | K40: =K18 -> 754.113 | L40: =L18 -> 752.202 | M40: =M18 -> 742.725 | ... BI40: =BI18 -> 1304.1289 | BK40: =SUMIF($F$1:$BI$1,BK$1,$F40:$BI40) -> 1940.706 | BL40: =SUMIF($F$1:$BI$1,BL$1,$F40:$BI40) -> 2782.721 | BM40: =SUMIF($F$1:$BI$1,BM$1,$F40:$BI40) -> 3069.652 | BN40: =SUMIF($F$1:$BI$1,BN$1,$F40:$BI40) -> 3156.047 | BO40: =SUMIF($F$1:$BI$1,BO$1,$F40:$BI40) -> 3238.448 | BP40: =SUMIF($F$1:$BI$1,BP$1,$F40:$BI40) -> 3608.527 | BQ40: =SUMIF($F$1:$BI$1,BQ$1,$F40:$BI40) -> 3923.003 | BR40: =SUMIF($F$1:$BI$1,BR$1,$F40:$BI40) -> 4055.147 | ... BX40: =SUMIF($F$1:$BI$1,BX$1,$F40:$BI40) -> 5152.4671
B41: Gross Profit | F41: =F39-F40 -> 243.898 | G41: =G39-G40 -> 319.707 | H41: =H39-H40 -> 327.19 | I41: =I39-I40 -> 324.927 | J41: =J39-J40 -> 332.021 | K41: =K39-K40 -> 415.178 | L41: =L39-L40 -> 410.324 | M41: =M39-M40 -> 383.424 | ... BI41: =BI39-BI40 -> 783.11485 | BK41: =SUMIF($F$1:$BI$1,BK$1,$F41:$BI41) -> 1215.722 | BL41: =SUMIF($F$1:$BI$1,BL$1,$F41:$BI41) -> 1540.947 | BM41: =SUMIF($F$1:$BI$1,BM$1,$F41:$BI41) -> 1555.712 | BN41: =SUMIF($F$1:$BI$1,BN$1,$F41:$BI41) -> 1670.502 | BO41: =SUMIF($F$1:$BI$1,BO$1,$F41:$BI41) -> 1768.909 | BP41: =SUMIF($F$1:$BI$1,BP$1,$F41:$BI41) -> 1954.187 | BQ41: =SUMIF($F$1:$BI$1,BQ$1,$F41:$BI41) -> 2277.954 | BR41: =SUMIF($F$1:$BI$1,BR$1,$F41:$BI41) -> 2598.711 | ... BX41: =SUMIF($F$1:$BI$1,BX$1,$F41:$BI41) -> 2960.7391
C42: SG&A | F42: =F20-F32-F34 -> 229.87 | G42: =G20-G32-G34 -> 263.702 | H42: =H20-H32-H34 -> 285.84 | I42: =I20-I32-I34 -> 301.297 | J42: =J20-J32-J34 -> 316.353 | K42: =K20-K32-K34 -> 365.348 | L42: =L20-L32-L34 -> 372.298 | M42: =M20-M32-M34 -> 382.847 | ... AS42: =AS20-AS32-AS34 -> 512.128 | AT42: =AT20-AT32 -> 464.58894 | AU42: =AU20-AU32 -> 498.87642 | AV42: =AV20-AV32 -> 531.44787 | AW42: =AW20-AW32 -> 542.05248 | AX42: =AX20-AX32 -> 480.84955 | AY42: =AY20-AY32 -> 516.33709 | AZ42: =AZ20-AZ32 -> 550.04855 | BA42: =BA20-BA32 -> 561.02432 | ... BI42: =BI20-BI32 -> 600.98327 | BK42: =SUMIF($F$1:$BI$1,BK$1,$F42:$BI42) -> 1080.709 | BL42: =SUMIF($F$1:$BI$1,BL$1,$F42:$BI42) -> 1436.846 | BM42: =SUMIF($F$1:$BI$1,BM$1,$F42:$BI42) -> 1492.204 | BN42: =SUMIF($F$1:$BI$1,BN$1,$F42:$BI42) -> 1487.703 | BO42: =SUMIF($F$1:$BI$1,BO$1,$F42:$BI42) -> 1455.531 | BP42: =SUMIF($F$1:$BI$1,BP$1,$F42:$BI42) -> 1515.016 | BQ42: =SUMIF($F$1:$BI$1,BQ$1,$F42:$BI42) -> 1636.907 | BR42: =SUMIF($F$1:$BI$1,BR$1,$F42:$BI42) -> 1764.26 | ... BX42: =SUMIF($F$1:$BI$1,BX$1,$F42:$BI42) -> 2258.4203
B43: Adj. EBIT | F43: =F41-F42 -> 14.028 | G43: =G41-G42 -> 56.005 | H43: =H41-H42 -> 41.35 | I43: =I41-I42 -> 23.63 | J43: =J41-J42 -> 15.668 | K43: =K41-K42 -> 49.83 | L43: =L41-L42 -> 38.026 | M43: =M41-M42 -> 0.577 | ... BI43: =BI41-BI42 -> 182.13158 | BK43: =SUMIF($F$1:$BI$1,BK$1,$F43:$BI43) -> 135.013 | BL43: =SUMIF($F$1:$BI$1,BL$1,$F43:$BI43) -> 104.101 | BM43: =SUMIF($F$1:$BI$1,BM$1,$F43:$BI43) -> 63.508 | BN43: =SUMIF($F$1:$BI$1,BN$1,$F43:$BI43) -> 182.799 | BO43: =SUMIF($F$1:$BI$1,BO$1,$F43:$BI43) -> 313.378 | BP43: =SUMIF($F$1:$BI$1,BP$1,$F43:$BI43) -> 439.171 | BQ43: =SUMIF($F$1:$BI$1,BQ$1,$F43:$BI43) -> 641.047 | BR43: =SUMIF($F$1:$BI$1,BR$1,$F43:$BI43) -> 834.451 | ... BX43: =SUMIF($F$1:$BI$1,BX$1,$F43:$BI43) -> 702.31882
...

Sheet Segment Build
A1: COKE | F1: 16 | G1: =F1 -> 16 | H1: =G1 -> 16 | I1: =H1 -> 16 | J1: =I1+1 -> 17 | K1: =J1 -> 17 | L1: =K1 -> 17 | M1: =L1 -> 17 | N1: =M1+1 -> 18 | O1: =N1 -> 18 | P1: =O1 -> 18 | Q1: =P1 -> 18 | R1: =Q1+1 -> 19 | S1: =R1 -> 19 | T1: =S1 -> 19 | U1: =T1 -> 19 | V1: =U1+1 -> 20 | W1: =V1 -> 20 | X1: =W1 -> 20 | Y1: =X1 -> 20 | Z1: =Y1+1 -> 21 | AA1: =Z1 -> 21 | AB1: =AA1 -> 21 | AC1: =AB1 -> 21 | AD1: =AC1+1 -> 22 | AE1: =AD1 -> 22 | AF1: =AE1 -> 22 | AG1: =AF1 -> 22 | AH1: =AG1+1 -> 23 | AI1: =AH1 -> 23 | AJ1: =AI1 -> 23 | AK1: =AJ1 -> 23 | AL1: =AK1+1 -> 24 | AM1: =AL1 -> 24 | AN1: =AM1 -> 24 | AO1: =AN1 -> 24 | AP1: =AO1+1 -> 25 | AQ1: =AP1 -> 25 | AR1: =AQ1 -> 25 | AS1: =AR1 -> 25 | AT1: =AS1+1 -> 26 | AU1: =AT1 -> 26 | AV1: =AU1 -> 26 | AW1: =AV1 -> 26 | AX1: =AW1+1 -> 27 | AY1: =AX1 -> 27 | AZ1: =AY1 -> 27 | BA1: =AZ1 -> 27 | BB1: =BA1+1 -> 28 | BC1: =BB1 -> 28 | BD1: =BC1 -> 28 | BE1: =BD1 -> 28 | BF1: =BE1+1 -> 29 | BG1: =BF1 -> 29 | BH1: =BG1 -> 29 | BI1: =BH1 -> 29 | BK1: 16 | BL1: 17 | BM1: 18 | BN1: 19 | BO1: 20 | BP1: 21 | BQ1: 22 | BR1: 23 | BS1: 24 | BT1: 25 | BU1: 26 | BV1: 27 | BW1: 28 | BX1: 29
A2: Coca-Cola Consolidated, Inc. | F2: Q1 | G2: Q2 | H2: Q3 | I2: Q4 | J2: =F2 -> Q1 | K2: =G2 -> Q2 | L2: =H2 -> Q3 | M2: =I2 -> Q4 | N2: =J2 -> Q1 | O2: =K2 -> Q2 | P2: =L2 -> Q3 | Q2: =M2 -> Q4 | ... BI2: =BE2 -> Q4 | BK2: Q4 | BL2: Q4 | BM2: Q4 | BN2: Q4 | BO2: Q4 | BP2: Q4 | BQ2: Q4 | BR2: Q4 | BS2: Q4 | BT2: Q4 | BU2: Q4 | BV2: Q4 | BW2: Q4 | BX2: Q4
A3: ($ in mm, except per share values) | F3: 90 | G3: 91 | H3: 92 | I3: 92 | J3: 90 | K3: 91 | L3: 92 | M3: 92 | N3: 90 | O3: 91 | P3: 92 | Q3: 92 | R3: 90 | S3: 91 | T3: 92 | U3: 92 | V3: 90 | W3: 91 | X3: 92 | Y3: 92 | Z3: 90 | AA3: 91 | AB3: 92 | AC3: 92 | AD3: 90 | AE3: 91 | AF3: 92 | AG3: 92 | AH3: 90 | AI3: 91 | AJ3: 92 | AK3: 92 | AL3: 90 | AM3: 91 | AN3: 92 | AO3: 92 | AP3: 90 | AQ3: 91 | AR3: 92 | AS3: 92 | AT3: 90 | AU3: 91 | AV3: 92 | AW3: 92 | AX3: 90 | AY3: 91 | AZ3: 92 | BA3: 92 | BB3: 90 | BC3: 91 | BD3: 92 | BE3: 92 | BF3: 90 | BG3: 91 | BH3: 92 | BI3: 92
F4: 42460 | G4: =EOMONTH(F4,3) -> 42551 | H4: =EOMONTH(G4,3) -> 42643 | I4: =EOMONTH(H4,3) -> 42735 | J4: =EOMONTH(I4,3) -> 42825 | K4: =EOMONTH(J4,3) -> 42916 | L4: =EOMONTH(K4,3) -> 43008 | M4: =EOMONTH(L4,3) -> 43100 | N4: =EOMONTH(M4,3) -> 43190 | ... BI4: =EOMONTH(BH4,3) -> 47483
F5: Q1 16 | G5: =G2&" "&G1 -> Q2 16 | H5: =H2&" "&H1 -> Q3 16 | I5: =I2&" "&I1 -> Q4 16 | J5: =J2&" "&J1 -> Q1 17 | K5: =K2&" "&K1 -> Q2 17 | L5: =L2&" "&L1 -> Q3 17 | M5: =M2&" "&M1 -> Q4 17 | N5: =N2&" "&N1 -> Q1 18 | ... BI5: =BI2&" "&BI1 -> Q4 29 | BK5: 2016 | BL5: 2017 | BM5: 2018 | BN5: 2019 | BO5: 2020 | BP5: 2021 | BQ5: 2022 | BR5: 2023 | BS5: 2024 | BT5: 2025 | BU5: 2026 | BV5: 2027 | BW5: 2028 | BX5: 2029
A6: x | B6: Segments
B8: Total Revenue | F8: =F17+F30+F38+F42 -> 625.456 | G8: =G17+G30+G38+G42 -> 840.384 | H8: =H17+H30+H38+H42 -> 849.028 | I8: =I17+I30+I38+I42 -> 841.56 | J8: =J17+J30+J38+J42 -> 865.702 | K8: =K17+K30+K38+K42 -> 1169.291 | L8: =L17+L30+L38+L42 -> 1162.526 | M8: =M17+M30+M38+M42 -> 1126.149 | ... BI8: =BI17+BI30+BI38+BI42 -> 2087.2437 | BK8: =SUMIF($F$1:$BI$1,BK$1,$F8:$BI8) -> 3156.428 | BL8: =SUMIF($F$1:$BI$1,BL$1,$F8:$BI8) -> 4323.668 | BM8: =SUMIF($F$1:$BI$1,BM$1,$F8:$BI8) -> 4625.364 | BN8: =SUMIF($F$1:$BI$1,BN$1,$F8:$BI8) -> 4826.549 | BO8: =SUMIF($F$1:$BI$1,BO$1,$F8:$BI8) -> 5007.357 | BP8: =SUMIF($F$1:$BI$1,BP$1,$F8:$BI8) -> 5562.714 | BQ8: =SUMIF($F$1:$BI$1,BQ$1,$F8:$BI8) -> 6204.72 | BR8: =SUMIF($F$1:$BI$1,BR$1,$F8:$BI8) -> 6668.672 | ... BX8: =SUMIF($F$1:$BI$1,BX$1,$F8:$BI8) -> 8113.2062
B9: Total Cases | F9: =F12+F25 -> 0 | G9: =G12+G25 -> 0 | H9: =H12+H25 -> 0 | I9: =I12+I25 -> 0 | J9: =J12+J25 -> 65.2 | K9: =K12+K25 -> 88.5 | L9: =L12+L25 -> 86.8 | M9: =M12+M25 -> 83.3 | ... BI9: =BI12+BI25 -> 95.673771 | BK9: =SUMIF($F$1:$BI$1,BK$1,$F9:$BI9) -> 0 | BL9: =SUMIF($F$1:$BI$1,BL$1,$F9:$BI9) -> 323.8 | BM9: =SUMIF($F$1:$BI$1,BM$1,$F9:$BI9) -> 337.7 | BN9: =SUMIF($F$1:$BI$1,BN$1,$F9:$BI9) -> 343.2 | BO9: =SUMIF($F$1:$BI$1,BO$1,$F9:$BI9) -> 358.8 | BP9: =SUMIF($F$1:$BI$1,BP$1,$F9:$BI9) -> 366.036 | BQ9: =SUMIF($F$1:$BI$1,BQ$1,$F9:$BI9) -> 360.348 | BR9: =SUMIF($F$1:$BI$1,BR$1,$F9:$BI9) -> 355.367 | ... BX9: =SUMIF($F$1:$BI$1,BX$1,$F9:$BI9) -> 370.61448
BM10: =BM9/BL9-1 -> 0.042927733 | BN10: =BN9/BM9-1 -> 0.016286645 | BO10: =BO9/BN9-1 -> 0.045454545 | BP10: =BP9/BO9-1 -> 0.020167224 | BQ10: =BQ9/BP9-1 -> -0.015539455 | BR10: =BR9/BQ9-1 -> -0.013822749 | BS10: =BS9/BR9-1 -> -0.0063708786 | BT10: =BT9/BS9-1 -> 0.0026762729 | ... BX10: =BX9/BW9-1 -> 0.01
B11: Sparkling Beverages
C12: Case Volume (mm cases) | F12: ='Canalyst HC - Q'!C42 -> 0 | G12: ='Canalyst HC - Q'!D42 -> 0 | H12: ='Canalyst HC - Q'!E42 -> 0 | I12: ='Canalyst HC - Q'!F42 -> 0 | J12: ='Canalyst HC - Q'!G42 -> 46.5528 | K12: ='Canalyst HC - Q'!H42 -> 60.0915 | L12: ='Canalyst HC - Q'!I42 -> 56.5068 | M12: ='Canalyst HC - Q'!J42 -> 61.2423 | ... AC12: ='Canalyst HC - Q'!Z42 -> 64.2728 | AD12: 60.182 | AE12: 66.738 | AF12: 63.656 | AG12: 61.317 | AH12: ='Canalyst HC - Q'!AE42 -> 61.317 | AI12: ='Canalyst HC - Q'!AF42 -> 67.9 | AJ12: ='Canalyst HC - Q'!AG42 -> 66.251 | AK12: ='Canalyst HC - Q'!AH42 -> 68.404 | AL12: ='Canalyst HC - Q'!AI42 -> 61.785 | AM12: ='Canalyst HC - Q'!AJ42 -> 67.662 | AN12: ='Canalyst HC - Q'!AK42 -> 66.781 | AO12: ='Canalyst HC - Q'!AL42 -> 70.458 | ... AS12: ='Canalyst HC - Q'!AP42 -> 72.938 | AT12: =AP12*(1+AT13) -> 65.07819 | AU12: =AQ12*(1+AU13) -> 66.81213 | AV12: =AR12*(1+AV13) -> 67.01805 | AW12: =AS12*(1+AW13) -> 72.20862 | AX12: =AT12*(1+AX13) -> 65.728972 | AY12: =AU12*(1+AY13) -> 67.480251 | AZ12: =AV12*(1+AZ13) -> 67.68823 | BA12: =AW12*(1+BA13) -> 72.930706 | ... BI12: =BE12*(1+BI13) -> 74.396613 | BK12: =SUMIF($F$1:$BI$1,BK$1,$F12:$BI12) -> 0 | BL12: =SUMIF($F$1:$BI$1,BL$1,$F12:$BI12) -> 224.3934 | BM12: =SUMIF($F$1:$BI$1,BM$1,$F12:$BI12) -> 241.7932 | BN12: =SUMIF($F$1:$BI$1,BN$1,$F12:$BI12) -> 242.6424 | BO12: =SUMIF($F$1:$BI$1,BO$1,$F12:$BI12) -> 253.3128 | BP12: =SUMIF($F$1:$BI$1,BP$1,$F12:$BI12) -> 254.028 | BQ12: =SUMIF($F$1:$BI$1,BQ$1,$F12:$BI12) -> 251.893 | BR12: =SUMIF($F$1:$BI$1,BR$1,$F12:$BI12) -> 263.872 | ... BX12: =SUMIF($F$1:$BI$1,BX$1,$F12:$BI12) -> 279.33211
C13: YoY Growth % | J13: =IF(F12=0,0,J12/F12-1) -> 0 | K13: =IF(G12=0,0,K12/G12-1) -> 0 | L13: =IF(H12=0,0,L12/H12-1) -> 0 | M13: =IF(I12=0,0,M12/I12-1) -> 0 | N13: =IF(J12=0,0,N12/J12-1) -> 0.20637212 | O13: =IF(K12=0,0,O12/K12-1) -> 0.054064219 | P13: =IF(L12=0,0,P12/L12-1) -> 0.040274799 | Q13: =IF(M12=0,0,Q12/M12-1) -> 0.037033227 | ... AS13: =IF(AO12=0,0,AS12/AO12-1) -> 0.035198274 | AT13: =OFFSET(AT13,LEFT(Summary!$D$4,1),0) -> 0.11 | AU13: =OFFSET(AU13,LEFT(Summary!$D$4,1),0) -> -0.01 | AV13: =OFFSET(AV13,LEFT(Summary!$D$4,1),0) -> -0.01 | AW13: =OFFSET(AW13,LEFT(Summary!$D$4,1),0) -> -0.01 | AX13: =OFFSET(AX13,LEFT(Summary!$D$4,1),0) -> 0.01 | AY13: =OFFSET(AY13,LEFT(Summary!$D$4,1),0) -> 0.01 | AZ13: =OFFSET(AZ13,LEFT(Summary!$D$4,1),0) -> 0.01 | BA13: =OFFSET(BA13,LEFT(Summary!$D$4,1),0) -> 0.01 | ... BI13: =OFFSET(BI13,LEFT(Summary!$D$4,1),0) -> 0.01 | BM13: =BM12/BL12-1 -> 0.077541496 | BN13: =BN12/BM12-1 -> 0.0035120922 | BO13: =BO12/BN12-1 -> 0.043975826 | BP13: =BP12/BO12-1 -> 0.0028233867 | BQ13: =BQ12/BP12-1 -> -0.0084045853 | BR13: =BR12/BQ12-1 -> 0.047555907 | BS13: =BS12/BR12-1 -> 0.010664261 | BT13: =BT12/BS12-1 -> 0.00023623287 | ... BX13: =BX12/BW12-1 -> 0.01
D14: Bull | AT14: =AT15+0.01 -> 0.12 | AU14: =AU15+0.01 -> 0 | AV14: =AV15+0.01 -> 0 | AW14: =AW15+0.01 -> 0 | AX14: =AX15+0.01 -> 0.02 | AY14: =AY15+0.01 -> 0.02 | AZ14: =AZ15+0.01 -> 0.02 | BA14: =BA15+0.01 -> 0.02 | ... BI14: =BI15+0.01 -> 0.02
D15: Base | AO15: street --> | AP15: 0.0061 | AQ15: 0.0217 | AR15: -0.0265 | AT15: 0.11 | AU15: -0.01 | AV15: -0.01 | AW15: -0.01 | AX15: 0.01 | AY15: 0.01 | AZ15: 0.01 | BA15: 0.01 | BB15: 0.01 | BC15: 0.01 | BD15: 0.01 | BE15: 0.01 | BF15: 0.01 | BG15: 0.01 | BH15: 0.01 | BI15: 0.01
D16: Bear | AT16: =AT15-0.01 -> 0.1 | AU16: =AU15-0.01 -> -0.02 | AV16: =AV15-0.01 -> -0.02 | AW16: =AW15-0.01 -> -0.02 | AX16: =AX15-0.02 -> -0.01 | AY16: =AY15-0.02 -> -0.01 | AZ16: =AZ15-0.02 -> -0.01 | BA16: =BA15-0.02 -> -0.01 | BB16: =BB15-0.02 -> -0.01 | BC16: =BC15-0.02 -> -0.01 | BD16: =BD15-0.02 -> -0.01 | BE16: =BE15-0.02 -> -0.01 | ... BI16: =BI15-0.02 -> -0.01
C17: Revenue | F17: ='Canalyst HC - Q'!C19 -> 352.67 | G17: ='Canalyst HC - Q'!D19 -> 464.859 | H17: ='Canalyst HC - Q'!E19 -> 455.748 | I17: ='Canalyst HC - Q'!F19 -> 491.281 | J17: ='Canalyst HC - Q'!G19 -> 479.76 | K17: ='Canalyst HC - Q'!H19 -> 607.623 | L17: ='Canalyst HC - Q'!I19 -> 582.71 | M17: ='Canalyst HC - Q'!J19 -> 615.528 | ... AS17: ='Canalyst HC - Q'!AP19 -> 1152.9 | AT17: =AT18*AT12 -> 1046.9247 | AU17: =AU18*AU12 -> 1079.848 | AV17: =AV18*AV12 -> 1083.0307 | AW17: =AW18*AW12 -> 1152.7847 | AX17: =AX18*AX12 -> 1078.5418 | AY17: =AY18*AY12 -> 1112.4594 | AZ17: =AZ18*AZ12 -> 1115.7382 | BA17: =BA18*BA12 -> 1187.5988 | ... BI17: =BI18*BI12 -> 1260.4129 | BK17: =SUMIF($F$1:$BI$1,BK$1,$F17:$BI17) -> 1764.558 | BL17: =SUMIF($F$1:$BI$1,BL$1,$F17:$BI17) -> 2285.621 | BM17: =SUMIF($F$1:$BI$1,BM$1,$F17:$BI17) -> 2395.213 | BN17: =SUMIF($F$1:$BI$1,BN$1,$F17:$BI17) -> 2582.478 | BO17: =SUMIF($F$1:$BI$1,BO$1,$F17:$BI17) -> 2760.827 | BP17: =SUMIF($F$1:$BI$1,BP$1,$F17:$BI17) -> 3020.887 | BQ17: =SUMIF($F$1:$BI$1,BQ$1,$F17:$BI17) -> 3521.181 | BR17: =SUMIF($F$1:$BI$1,BR$1,$F17:$BI17) -> 3908.763 | ... BX17: =SUMIF($F$1:$BI$1,BX$1,$F17:$BI17) -> 4769.8953
C18: Avg Sales / Case ($) | F18: =IF(F12=0,0,F17/F12) -> 0 | G18: =IF(G12=0,0,G17/G12) -> 0 | H18: =IF(H12=0,0,H17/H12) -> 0 | I18: =IF(I12=0,0,I17/I12) -> 0 | J18: =IF(J12=0,0,J17/J12) -> 10.305717 | K18: =IF(K12=0,0,K17/K12) -> 10.11163 | L18: =IF(L12=0,0,L17/L12) -> 10.31221 | M18: =IF(M12=0,0,M17/M12) -> 10.0507 | ... AS18: =IF(AS12=0,0,AS17/AS12) -> 15.806575 | AT18: =AP18*(1+AT19) -> 16.087182 | AU18: =AQ18*(1+AU19) -> 16.162454 | AV18: =AR18*(1+AV19) -> 16.160283 | AW18: =AS18*(1+AW19) -> 15.964641 | AX18: =AT18*(1+AX19) -> 16.408925 | AY18: =AU18*(1+AY19) -> 16.485703 | AZ18: =AV18*(1+AZ19) -> 16.483489 | BA18: =AW18*(1+BA19) -> 16.283934 | ... BI18: =BE18*(1+BI19) -> 16.941805 | BM18: =BM17/BL17-1 -> 0.047948457 | BN18: =BN17/BM17-1 -> 0.078183026 | BO18: =BO17/BN17-1 -> 0.069061189 | BP18: =BP17/BO17-1 -> 0.094196413 | BQ18: =BQ17/BP17-1 -> 0.16561162 | BR18: =BR17/BQ17-1 -> 0.11007159 | BS18: =BS17/BR17-1 -> 0.053800397 | BT18: =BT17/BS17-1 -> 0.031749022 | ... BX18: =BX17/BW17-1 -> 0.0302
C19: YoY Growth % | J19: =IF(F18=0,0,J18/F18-1) -> 0 | K19: =IF(G18=0,0,K18/G18-1) -> 0 | L19: =IF(H18=0,0,L18/H18-1) -> 0 | M19: =IF(I18=0,0,M18/I18-1) -> 0 | N19: =IF(J18=0,0,N18/J18-1) -> -0.032247901 | O19: =IF(K18=0,0,O18/K18-1) -> -0.0050878951 | P19: =IF(L18=0,0,P18/L18-1) -> 0.022314337 | Q19: =IF(M18=0,0,Q18/M18-1) -> -0.094207775 | ... AS19: =IF(AO18=0,0,AS18/AO18-1) -> 0.027872352 | AT19: =OFFSET(AT19,LEFT(Summary!$D$4,1),0) -> 0.01 | AU19: =OFFSET(AU19,LEFT(Summary!$D$4,1),0) -> 0.01 | AV19: =OFFSET(AV19,LEFT(Summary!$D$4,1),0) -> 0.01 | AW19: =OFFSET(AW19,LEFT(Summary!$D$4,1),0) -> 0.01 | AX19: =OFFSET(AX19,LEFT(Summary!$D$4,1),0) -> 0.02 | AY19: =OFFSET(AY19,LEFT(Summary!$D$4,1),0) -> 0.02 | AZ19: =OFFSET(AZ19,LEFT(Summary!$D$4,1),0) -> 0.02 | BA19: =OFFSET(BA19,LEFT(Summary!$D$4,1),0) -> 0.02 | ... BI19: =OFFSET(BI19,LEFT(Summary!$D$4,1),0) -> 0.02
D20: Bull | AT20: =AT21+0.01 -> 0.02 | AU20: =AU21+0.01 -> 0.02 | AV20: =AV21+0.01 -> 0.02 | AW20: =AW21+0.01 -> 0.02 | AX20: =AX21+0.01 -> 0.03 | AY20: =AY21+0.01 -> 0.03 | AZ20: =AZ21+0.01 -> 0.03 | BA20: =BA21+0.01 -> 0.03 | ... BI20: =BI21+0.01 -> 0.03
D21: Base | AT21: 0.01 | AU21: 0.01 | AV21: 0.01 | AW21: 0.01 | AX21: 0.02 | AY21: 0.02 | AZ21: 0.02 | BA21: 0.02 | BB21: 0.02 | BC21: 0.02 | BD21: 0.02 | BE21: 0.02 | BF21: 0.02 | BG21: 0.02 | BH21: 0.02 | BI21: 0.02
D22: Bear | AT22: =AT21-0.01 -> 0 | AU22: =AU21-0.01 -> 0 | AV22: =AV21-0.01 -> 0 | AW22: =AW21-0.01 -> 0 | AX22: =AX21-0.01 -> 0.01 | AY22: =AY21-0.01 -> 0.01 | AZ22: =AZ21-0.01 -> 0.01 | BA22: =BA21-0.01 -> 0.01 | ... BI22: =BI21-0.01 -> 0.01
B24: Still Beverages
C25: Case Volume (mm cases) | F25: ='Canalyst HC - Q'!C43 -> 0 | G25: ='Canalyst HC - Q'!D43 -> 0 | H25: ='Canalyst HC - Q'!E43 -> 0 | I25: ='Canalyst HC - Q'!F43 -> 0 | J25: ='Canalyst HC - Q'!G43 -> 18.6472 | K25: ='Canalyst HC - Q'!H43 -> 28.4085 | L25: ='Canalyst HC - Q'!I43 -> 30.2932 | M25: ='Canalyst HC - Q'!J43 -> 22.0577 | ... AC25: ='Canalyst HC - Q'!Z43 -> 24.9632 | AD25: 26.22 | AE25: 30.67 | AF25: 30.412 | AG25: 21.153 | AH25: ='Canalyst HC - Q'!AE43 -> 21.153 | AI25: ='Canalyst HC - Q'!AF43 -> 24.655 | AJ25: ='Canalyst HC - Q'!AG43 -> 25.546 | AK25: ='Canalyst HC - Q'!AH43 -> 20.141 | AL25: ='Canalyst HC - Q'!AI43 -> 20.326 | AM25: ='Canalyst HC - Q'!AJ43 -> 23.791 | AN25: ='Canalyst HC - Q'!AK43 -> 23.078 | AO25: ='Canalyst HC - Q'!AL43 -> 19.222 | ... AS25: ='Canalyst HC - Q'!AP43 -> 20.86 | AT25: =AP25*(1+AT26) -> 20.08878 | AU25: =AQ25*(1+AU26) -> 22.98681 | AV25: =AR25*(1+AV26) -> 24.87078 | AW25: =AS25*(1+AW26) -> 20.6514 | AX25: =AT25*(1+AX26) -> 20.289668 | AY25: =AU25*(1+AY26) -> 23.216678 | AZ25: =AV25*(1+AZ26) -> 25.119488 | BA25: =AW25*(1+BA26) -> 20.857914 | ... BI25: =BE25*(1+BI26) -> 21.277158 | BK25: =SUMIF($F$1:$BI$1,BK$1,$F25:$BI25) -> 0 | BL25: =SUMIF($F$1:$BI$1,BL$1,$F25:$BI25) -> 99.4066 | BM25: =SUMIF($F$1:$BI$1,BM$1,$F25:$BI25) -> 95.9068 | BN25: =SUMIF($F$1:$BI$1,BN$1,$F25:$BI25) -> 100.5576 | BO25: =SUMIF($F$1:$BI$1,BO$1,$F25:$BI25) -> 105.4872 | BP25: =SUMIF($F$1:$BI$1,BP$1,$F25:$BI25) -> 112.008 | BQ25: =SUMIF($F$1:$BI$1,BQ$1,$F25:$BI25) -> 108.455 | BR25: =SUMIF($F$1:$BI$1,BR$1,$F25:$BI25) -> 91.495 | ... BX25: =SUMIF($F$1:$BI$1,BX$1,$F25:$BI25) -> 91.282371
C26: YoY Growth % | J26: =IF(F25=0,0,J25/F25-1) -> 0 | K26: =IF(G25=0,0,K25/G25-1) -> 0 | L26: =IF(H25=0,0,L25/H25-1) -> 0 | M26: =IF(I25=0,0,M25/I25-1) -> 0 | N26: =IF(J25=0,0,N25/J25-1) -> 0.17122142 | O26: =IF(K25=0,0,O25/K25-1) -> -0.058038967 | P26: =IF(L25=0,0,P25/L25-1) -> -0.078426842 | Q26: =IF(M25=0,0,Q25/M25-1) -> -0.12095549 | ... AS26: =IF(AO25=0,0,AS25/AO25-1) -> 0.085214858 | AT26: =OFFSET(AT26,LEFT(Summary!$D$4,1),0) -> 0.11 | AU26: =OFFSET(AU26,LEFT(Summary!$D$4,1),0) -> -0.01 | AV26: =OFFSET(AV26,LEFT(Summary!$D$4,1),0) -> -0.01 | AW26: =OFFSET(AW26,LEFT(Summary!$D$4,1),0) -> -0.01 | AX26: =OFFSET(AX26,LEFT(Summary!$D$4,1),0) -> 0.01 | AY26: =OFFSET(AY26,LEFT(Summary!$D$4,1),0) -> 0.01 | AZ26: =OFFSET(AZ26,LEFT(Summary!$D$4,1),0) -> 0.01 | BA26: =OFFSET(BA26,LEFT(Summary!$D$4,1),0) -> 0.01 | ... BI26: =OFFSET(BI26,LEFT(Summary!$D$4,1),0) -> 0.01 | BM26: =BM25/BL25-1 -> -0.035206918 | BN26: =BN25/BM25-1 -> 0.048492912 | BO26: =BO25/BN25-1 -> 0.04902265 | BP26: =BP25/BO25-1 -> 0.061816031 | BQ26: =BQ25/BP25-1 -> -0.031720949 | BR26: =BR25/BQ25-1 -> -0.15637822 | BS26: =BS25/BR25-1 -> -0.055500301 | BT26: =BT25/BS25-1 -> 0.010206325 | ... BX26: =BX25/BW25-1 -> 0.01
D27: Bull | AT27: =AT28+0.01 -> 0.12 | AU27: =AU28+0.01 -> 0 | AV27: =AV28+0.01 -> 0 | AW27: =AW28+0.01 -> 0 | AX27: =AX28+0.01 -> 0.02 | AY27: =AY28+0.01 -> 0.02 | AZ27: =AZ28+0.01 -> 0.02 | BA27: =BA28+0.01 -> 0.02 | ... BI27: =BI28+0.01 -> 0.02
D28: Base | AT28: 0.11 | AU28: -0.01 | AV28: -0.01 | AW28: -0.01 | AX28: 0.01 | AY28: 0.01 | AZ28: 0.01 | BA28: 0.01 | BB28: 0.01 | BC28: 0.01 | BD28: 0.01 | BE28: 0.01 | BF28: 0.01 | BG28: 0.01 | BH28: 0.01 | BI28: 0.01
D29: Bear | AT29: =AT28-0.01 -> 0.1 | AU29: =AU28-0.01 -> -0.02 | AV29: =AV28-0.01 -> -0.02 | AW29: =AW28-0.01 -> -0.02 | AX29: =AX28-0.02 -> -0.01 | AY29: =AY28-0.02 -> -0.01 | AZ29: =AZ28-0.02 -> -0.01 | BA29: =BA28-0.02 -> -0.01 | BB29: =BB28-0.02 -> -0.01 | BC29: =BC28-0.02 -> -0.01 | BD29: =BD28-0.02 -> -0.01 | BE29: =BE28-0.02 -> -0.01 | ... BI29: =BI28-0.02 -> -0.01
C30: Revenue | F30: ='Canalyst HC - Q'!C20 -> 166.19 | G30: ='Canalyst HC - Q'!D20 -> 246.371 | H30: ='Canalyst HC - Q'!E20 -> 261.508 | I30: ='Canalyst HC - Q'!F20 -> 218.056 | J30: ='Canalyst HC - Q'!G20 -> 256.058 | K30: ='Canalyst HC - Q'!H20 -> 368.955 | L30: ='Canalyst HC - Q'!I20 -> 384.495 | M30: ='Canalyst HC - Q'!J20 -> 316.461 | ... AS30: ='Canalyst HC - Q'!AP20 -> 584.4 | AT30: =AT31*AT25 -> 570.81591 | AU30: =AU31*AU25 -> 626.01539 | AV30: =AV31*AV25 -> 643.22267 | AW30: =AW31*AW25 -> 584.34156 | AX30: =AX31*AX25 -> 588.05455 | AY30: =AY31*AY25 -> 644.92106 | AZ30: =AZ31*AZ25 -> 662.648 | BA30: =BA31*BA25 -> 601.98868 | ... BI30: =BI31*BI25 -> 638.89783 | BK30: =SUMIF($F$1:$BI$1,BK$1,$F30:$BI30) -> 892.125 | BL30: =SUMIF($F$1:$BI$1,BL$1,$F30:$BI30) -> 1325.969 | BM30: =SUMIF($F$1:$BI$1,BM$1,$F30:$BI30) -> 1471.491 | BN30: =SUMIF($F$1:$BI$1,BN$1,$F30:$BI30) -> 1558.944 | BO30: =SUMIF($F$1:$BI$1,BO$1,$F30:$BI30) -> 1641.716 | BP30: =SUMIF($F$1:$BI$1,BP$1,$F30:$BI30) -> 1861.162 | BQ30: =SUMIF($F$1:$BI$1,BQ$1,$F30:$BI30) -> 2023.955 | BR30: =SUMIF($F$1:$BI$1,BR$1,$F30:$BI30) -> 2147.823 | ... BX30: =SUMIF($F$1:$BI$1,BX$1,$F30:$BI30) -> 2650.746
